Workbook

Sheet 3-Spieler
B1: GC Iffeldorf
A2: Spieler | B2: Ludwig | K2: Andreas | T2: Peter | AC2: =B2 -> Ludwig | AH2: =K2 -> Andreas | AM2: =T2 -> Peter
A3: HCP | F3: 17.4 | O3: 21.3 | X3: 26.3
A4: Spielvorgabe | F4: 19 | O4: 24 | X4: 26
A5: Vorgabeklasse | F5: =IF(F3<4.4,1,IF(AND(F3>=4.5,F3<=11.4),2,IF(AND(F3>=11.5,F3<=18.4),3,IF(AND(F3>=18.5,F3<=26.4),4,IF(AND(F3>=26.5,F3<=36),5,IF(F3>=36,6)))))) -> 3 | O5: =IF(O3<4.4,1,IF(AND(O3>=4.5,O3<=11.4),2,IF(AND(O3>=11.5,O3<=18.4),3,IF(AND(O3>=18.5,O3<=26.4),4,IF(AND(O3>=26.5,O3<=36),5,IF(O3>=36,6)))))) -> 4 | X5: =IF(X3<4.4,1,IF(AND(X3>=4.5,X3<=11.4),2,IF(AND(X3>=11.5,X3<=18.4),3,IF(AND(X3>=18.5,X3<=26.4),4,IF(AND(X3>=26.5,X3<=36),5,IF(X3>=36,6)))))) -> 4
A6: Pufferzone | F6: =VLOOKUP(F5,HCP!$A$6:$C$11,3,FALSE) -> 33 | O6: =VLOOKUP(O5,HCP!$A$6:$C$11,3,FALSE) -> 32 | X6: =VLOOKUP(X5,HCP!$A$6:$C$11,3,FALSE) -> 32
F7: =IF(I31>36,"Herabsetzung",IF(AND(I31<=36,I31>=F6),"Puffer","Heraufsetzung")) -> Heraufsetzung | O7: =IF(R31>36,"Herabsetzung",IF(AND(R31<=36,R31>=O6),"Puffer","Heraufsetzung")) -> Heraufsetzung | X7: =IF(AA31>36,"Herabsetzung",IF(AND(AA31<=36,AA31>=X6),"Puffer","Heraufsetzung")) -> Heraufsetzung
A8: Neues HCP | F8: =IF(F7="Heraufsetzung",INDEX(HCP!$C$395:$D$755,MATCH(F3,HCP!$C$394:$C$755,0),MATCH($A$8,HCP!$D$394,0)),IF(F7="Puffer",F3,IF(F7="Herabsetzung",INDEX(HCP!$C$29:$AK$389,MATCH(F3,HCP!$C$29:$C$389,0),MATCH(I31,HCP!$C$28:$AK$28,0))))) -> 17.5 | O8: =IF(O7="Heraufsetzung",INDEX(HCP!$C$395:$D$755,MATCH(O3,HCP!$C$394:$C$755,0),MATCH($A$8,HCP!$D$394,0)),IF(O7="Puffer",O3,IF(O7="Herabsetzung",INDEX(HCP!$C$29:$AK$389,MATCH(O3,HCP!$C$29:$C$389,0),MATCH(R31,HCP!$C$28:$AK$28,0))))) -> 21.4 | X8: =IF(X7="Heraufsetzung",INDEX(HCP!$C$395:$D$755,MATCH(X3,HCP!$C$394:$C$755,0),MATCH($A$8,HCP!$D$394,0)),IF(X7="Puffer",X3,IF(X7="Herabsetzung",INDEX(HCP!$C$29:$AK$389,MATCH(X3,HCP!$C$29:$C$389,0),MATCH(AA31,HCP!$C$28:$AK$28,0))))) -> 26.4
C9: HCP | D9: PAR | F9: Spv | G9: Schläge | H9: Brutto | I9: Netto | L9: HCP | M9: PAR | O9: Spv | P9: Schläge | Q9: Brutto | R9: Netto | U9: HCP | V9: PAR | X9: Spv | Y9: Schläge | Z9: Brutto | AA9: Netto | AC9: Allein | AD9: Zwei | AE9: Zwei | AF9: Drei | AH9: Allein | AI9: Zwei | AJ9: Zwei | AK9: Drei | AM9: Allein | AN9: Zwei | AO9: Zwei | AP9: Drei
B10: Bahn 1 | C10: 3 | D10: 4 | F10: =INDEX(Basis!$C$2:$BJ$19,MATCH($C10,Basis!$B$2:$B$19,0),MATCH(F$4,Basis!$C$1:$BJ$1,0)) -> 1 | H10: =IF(G10="",0,IF(G10-D10=0,2,IF(G10-D10=-1,3,IF(G10-D10=-2,4,IF(G10-D10=-3,5,IF(G10-D10=-4,6,IF(G10-D10=1,1,IF(G10-D10>=2,0,)))))))) -> 0 | I10: =IF(G10="",0,IF(G10-F10-D10=0,2,IF(G10-F10-D10=-1,3,IF(G10-F10-D10=-2,4,IF(G10-F10-D10=-3,5,IF(G10-F10-D10=-4,6,IF(G10-F10-D10=1,1,IF(G10-F10-D10>=2,0,)))))))) -> 0 | K10: Bahn 1 | L10: =C10 -> 3 | M10: =D10 -> 4 | O10: =INDEX(Basis!$C$2:$BJ$19,MATCH($C10,Basis!$B$2:$B$19,0),MATCH(O$4,Basis!$C$1:$BJ$1,0)) -> 2 | Q10: =IF(P10="",0,IF(P10-M10=0,2,IF(P10-M10=-1,3,IF(P10-M10=-2,4,IF(P10-M10=-3,5,IF(P10-M10=-4,6,IF(P10-M10=1,1,IF(P10-M10>=2,0,)))))))) -> 0 | R10: =IF(P10="",0,IF(P10-O10-M10=0,2,IF(P10-O10-M10=-1,3,IF(P10-O10-M10=-2,4,IF(P10-O10-M10=-3,5,IF(P10-O10-M10=-4,6,IF(P10-O10-M10=1,1,IF(P10-O10-M10>=2,0,)))))))) -> 0 | T10: Bahn 1 | U10: =C10 -> 3 | V10: =D10 -> 4 | X10: =INDEX(Basis!$C$2:$BJ$19,MATCH($U10,Basis!$B$2:$B$19,0),MATCH(X$4,Basis!$C$1:$BJ$1,0)) -> 2 | Z10: =IF(Y10="",0,IF(Y10-V10=0,2,IF(Y10-V10=-1,3,IF(Y10-V10=-2,4,IF(Y10-V10=-3,5,IF(Y10-V10=-4,6,IF(Y10-V10=1,1,IF(Y10-V10>=2,0,)))))))) -> 0 | AA10: =IF(Y10="",0,IF(Y10-X10-V10=0,2,IF(Y10-X10-V10=-1,3,IF(Y10-X10-V10=-2,4,IF(Y10-X10-V10=-3,5,IF(Y10-X10-V10=-4,6,IF(Y10-X10-V10=1,1,IF(Y10-X10-V10>=2,0,)))))))) -> 0 | AC10: =IF(AND(G10<P10,G10<Y10),2,0) -> 0 | AD10: =IF(AND(G10<P10,G10=Y10),1,0) -> 0 | AE10: =IF(AND(G10=P10,G10<Y10),1,0) -> 0 | AF10: =IF(AND(G10=P10,G10=Y10),1,0) -> 1 | AH10: =IF(AND(P10<G10,P10<Y10),2,0) -> 0 | AI10: =IF(AND(P10=G10,P10<Y10),1,0) -> 0 | AJ10: =IF(AND(P10=Y10,P10<G10),1,0) -> 0 | AK10: =IF(AND(P10=G10,P10=Y10),1,0) -> 1 | AM10: =IF(AND(Y10<G10,Y10<P10),2,0) -> 0 | AN10: =IF(AND(Y10=G10,Y10<P10),1,0) -> 0 | AO10: =IF(AND(Y10=P10,Y10<G10),1,0) -> 0 | AP10: =IF(AND(Y10=G10,Y10=P10),1,0) -> 1
B11: Bahn 2 | C11: 9 | D11: 5 | F11: =INDEX(Basis!$C$2:$BJ$19,MATCH($C11,Basis!$B$2:$B$19,0),MATCH(F$4,Basis!$C$1:$BJ$1,0)) -> 1 | H11: =IF(G11="",0,IF(G11-D11=0,2,IF(G11-D11=-1,3,IF(G11-D11=-2,4,IF(G11-D11=-3,5,IF(G11-D11=-4,6,IF(G11-D11=1,1,IF(G11-D11>=2,0,)))))))) -> 0 | I11: =IF(G11="",0,IF(G11-F11-D11=0,2,IF(G11-F11-D11=-1,3,IF(G11-F11-D11=-2,4,IF(G11-F11-D11=-3,5,IF(G11-F11-D11=-4,6,IF(G11-F11-D11=1,1,IF(G11-F11-D11>=2,0,)))))))) -> 0 | K11: Bahn 2 | L11: =C11 -> 9 | M11: =D11 -> 5 | O11: =INDEX(Basis!$C$2:$BJ$19,MATCH($C11,Basis!$B$2:$B$19,0),MATCH(O$4,Basis!$C$1:$BJ$1,0)) -> 1 | Q11: =IF(P11="",0,IF(P11-M11=0,2,IF(P11-M11=-1,3,IF(P11-M11=-2,4,IF(P11-M11=-3,5,IF(P11-M11=-4,6,IF(P11-M11=1,1,IF(P11-M11>=2,0,)))))))) -> 0 | R11: =IF(P11="",0,IF(P11-O11-M11=0,2,IF(P11-O11-M11=-1,3,IF(P11-O11-M11=-2,4,IF(P11-O11-M11=-3,5,IF(P11-O11-M11=-4,6,IF(P11-O11-M11=1,1,IF(P11-O11-M11>=2,0,)))))))) -> 0 | T11: Bahn 2 | U11: =C11 -> 9 | V11: =D11 -> 5 | X11: =INDEX(Basis!$C$2:$BJ$19,MATCH($U11,Basis!$B$2:$B$19,0),MATCH(X$4,Basis!$C$1:$BJ$1,0)) -> 1 | Z11: =IF(Y11="",0,IF(Y11-V11=0,2,IF(Y11-V11=-1,3,IF(Y11-V11=-2,4,IF(Y11-V11=-3,5,IF(Y11-V11=-4,6,IF(Y11-V11=1,1,IF(Y11-V11>=2,0,)))))))) -> 0 | AA11: =IF(Y11="",0,IF(Y11-X11-V11=0,2,IF(Y11-X11-V11=-1,3,IF(Y11-X11-V11=-2,4,IF(Y11-X11-V11=-3,5,IF(Y11-X11-V11=-4,6,IF(Y11-X11-V11=1,1,IF(Y11-X11-V11>=2,0,)))))))) -> 0 | AC11: =IF(AND(G11<P11,G11<Y11),2,0) -> 0 | AD11: =IF(AND(G11<P11,G11=Y11),1,0) -> 0 | AE11: =IF(AND(G11=P11,G11<Y11),1,0) -> 0 | AF11: =IF(AND(G11=P11,G11=Y11),1,0) -> 1 | AH11: =IF(AND(P11<G11,P11<Y11),2,0) -> 0 | AI11: =IF(AND(P11=G11,P11<Y11),1,0) -> 0 | AJ11: =IF(AND(P11=Y11,P11<G11),1,0) -> 0 | AK11: =IF(AND(P11=G11,P11=Y11),1,0) -> 1 | AM11: =IF(AND(Y11<G11,Y11<P11),2,0) -> 0 | AN11: =IF(AND(Y11=G11,Y11<P11),1,0) -> 0 | AO11: =IF(AND(Y11=P11,Y11<G11),1,0) -> 0 | AP11: =IF(AND(Y11=G11,Y11=P11),1,0) -> 1
B12: Bahn 3 | C12: 7 | D12: 4 | F12: =INDEX(Basis!$C$2:$BJ$19,MATCH($C12,Basis!$B$2:$B$19,0),MATCH(F$4,Basis!$C$1:$BJ$1,0)) -> 1 | H12: =IF(G12="",0,IF(G12-D12=0,2,IF(G12-D12=-1,3,IF(G12-D12=-2,4,IF(G12-D12=-3,5,IF(G12-D12=-4,6,IF(G12-D12=1,1,IF(G12-D12>=2,0,)))))))) -> 0 | I12: =IF(G12="",0,IF(G12-F12-D12=0,2,IF(G12-F12-D12=-1,3,IF(G12-F12-D12=-2,4,IF(G12-F12-D12=-3,5,IF(G12-F12-D12=-4,6,IF(G12-F12-D12=1,1,IF(G12-F12-D12>=2,0,)))))))) -> 0 | K12: Bahn 3 | L12: =C12 -> 7 | M12: =D12 -> 4 | O12: =INDEX(Basis!$C$2:$BJ$19,MATCH($C12,Basis!$B$2:$B$19,0),MATCH(O$4,Basis!$C$1:$BJ$1,0)) -> 1 | Q12: =IF(P12="",0,IF(P12-M12=0,2,IF(P12-M12=-1,3,IF(P12-M12=-2,4,IF(P12-M12=-3,5,IF(P12-M12=-4,6,IF(P12-M12=1,1,IF(P12-M12>=2,0,)))))))) -> 0 | R12: =IF(P12="",0,IF(P12-O12-M12=0,2,IF(P12-O12-M12=-1,3,IF(P12-O12-M12=-2,4,IF(P12-O12-M12=-3,5,IF(P12-O12-M12=-4,6,IF(P12-O12-M12=1,1,IF(P12-O12-M12>=2,0,)))))))) -> 0 | T12: Bahn 3 | U12: =C12 -> 7 | V12: =D12 -> 4 | X12: =INDEX(Basis!$C$2:$BJ$19,MATCH($U12,Basis!$B$2:$B$19,0),MATCH(X$4,Basis!$C$1:$BJ$1,0)) -> 2 | Z12: =IF(Y12="",0,IF(Y12-V12=0,2,IF(Y12-V12=-1,3,IF(Y12-V12=-2,4,IF(Y12-V12=-3,5,IF(Y12-V12=-4,6,IF(Y12-V12=1,1,IF(Y12-V12>=2,0,)))))))) -> 0 | AA12: =IF(Y12="",0,IF(Y12-X12-V12=0,2,IF(Y12-X12-V12=-1,3,IF(Y12-X12-V12=-2,4,IF(Y12-X12-V12=-3,5,IF(Y12-X12-V12=-4,6,IF(Y12-X12-V12=1,1,IF(Y12-X12-V12>=2,0,)))))))) -> 0 | AC12: =IF(AND(G12<P12,G12<Y12),2,0) -> 0 | AD12: =IF(AND(G12<P12,G12=Y12),1,0) -> 0 | AE12: =IF(AND(G12=P12,G12<Y12),1,0) -> 0 | AF12: =IF(AND(G12=P12,G12=Y12),1,0) -> 1 | AH12: =IF(AND(P12<G12,P12<Y12),2,0) -> 0 | AI12: =IF(AND(P12=G12,P12<Y12),1,0) -> 0 | AJ12: =IF(AND(P12=Y12,P12<G12),1,0) -> 0 | AK12: =IF(AND(P12=G12,P12=Y12),1,0) -> 1 | AM12: =IF(AND(Y12<G12,Y12<P12),2,0) -> 0 | AN12: =IF(AND(Y12=G12,Y12<P12),1,0) -> 0 | AO12: =IF(AND(Y12=P12,Y12<G12),1,0) -> 0 | AP12: =IF(AND(Y12=G12,Y12=P12),1,0) -> 1
B13: Bahn 4 | C13: 1 | D13: 5 | F13: =INDEX(Basis!$C$2:$BJ$19,MATCH($C13,Basis!$B$2:$B$19,0),MATCH(F$4,Basis!$C$1:$BJ$1,0)) -> 2 | H13: =IF(G13="",0,IF(G13-D13=0,2,IF(G13-D13=-1,3,IF(G13-D13=-2,4,IF(G13-D13=-3,5,IF(G13-D13=-4,6,IF(G13-D13=1,1,IF(G13-D13>=2,0,)))))))) -> 0 | I13: =IF(G13="",0,IF(G13-F13-D13=0,2,IF(G13-F13-D13=-1,3,IF(G13-F13-D13=-2,4,IF(G13-F13-D13=-3,5,IF(G13-F13-D13=-4,6,IF(G13-F13-D13=1,1,IF(G13-F13-D13>=2,0,)))))))) -> 0 | K13: Bahn 4 | L13: =C13 -> 1 | M13: =D13 -> 5 | O13: =INDEX(Basis!$C$2:$BJ$19,MATCH($C13,Basis!$B$2:$B$19,0),MATCH(O$4,Basis!$C$1:$BJ$1,0)) -> 2 | Q13: =IF(P13="",0,IF(P13-M13=0,2,IF(P13-M13=-1,3,IF(P13-M13=-2,4,IF(P13-M13=-3,5,IF(P13-M13=-4,6,IF(P13-M13=1,1,IF(P13-M13>=2,0,)))))))) -> 0 | R13: =IF(P13="",0,IF(P13-O13-M13=0,2,IF(P13-O13-M13=-1,3,IF(P13-O13-M13=-2,4,IF(P13-O13-M13=-3,5,IF(P13-O13-M13=-4,6,IF(P13-O13-M13=1,1,IF(P13-O13-M13>=2,0,)))))))) -> 0 | T13: Bahn 4 | U13: =C13 -> 1 | V13: =D13 -> 5 | X13: =INDEX(Basis!$C$2:$BJ$19,MATCH($U13,Basis!$B$2:$B$19,0),MATCH(X$4,Basis!$C$1:$BJ$1,0)) -> 2 | Z13: =IF(Y13="",0,IF(Y13-V13=0,2,IF(Y13-V13=-1,3,IF(Y13-V13=-2,4,IF(Y13-V13=-3,5,IF(Y13-V13=-4,6,IF(Y13-V13=1,1,IF(Y13-V13>=2,0,)))))))) -> 0 | AA13: =IF(Y13="",0,IF(Y13-X13-V13=0,2,IF(Y13-X13-V13=-1,3,IF(Y13-X13-V13=-2,4,IF(Y13-X13-V13=-3,5,IF(Y13-X13-V13=-4,6,IF(Y13-X13-V13=1,1,IF(Y13-X13-V13>=2,0,)))))))) -> 0 | AC13: =IF(AND(G13<P13,G13<Y13),2,0) -> 0 | AD13: =IF(AND(G13<P13,G13=Y13),1,0) -> 0 | AE13: =IF(AND(G13=P13,G13<Y13),1,0) -> 0 | AF13: =IF(AND(G13=P13,G13=Y13),1,0) -> 1 | AH13: =IF(AND(P13<G13,P13<Y13),2,0) -> 0 | AI13: =IF(AND(P13=G13,P13<Y13),1,0) -> 0 | AJ13: =IF(AND(P13=Y13,P13<G13),1,0) -> 0 | AK13: =IF(AND(P13=G13,P13=Y13),1,0) -> 1 | AM13: =IF(AND(Y13<G13,Y13<P13),2,0) -> 0 | AN13: =IF(AND(Y13=G13,Y13<P13),1,0) -> 0 | AO13: =IF(AND(Y13=P13,Y13<G13),1,0) -> 0 | AP13: =IF(AND(Y13=G13,Y13=P13),1,0) -> 1
B14: Bahn 5 | C14: 17 | D14: 3 | F14: =INDEX(Basis!$C$2:$BJ$19,MATCH($C14,Basis!$B$2:$B$19,0),MATCH(F$4,Basis!$C$1:$BJ$1,0)) -> 1 | H14: =IF(G14="",0,IF(G14-D14=0,2,IF(G14-D14=-1,3,IF(G14-D14=-2,4,IF(G14-D14=-3,5,IF(G14-D14=-4,6,IF(G14-D14=1,1,IF(G14-D14>=2,0,)))))))) -> 0 | I14: =IF(G14="",0,IF(G14-F14-D14=0,2,IF(G14-F14-D14=-1,3,IF(G14-F14-D14=-2,4,IF(G14-F14-D14=-3,5,IF(G14-F14-D14=-4,6,IF(G14-F14-D14=1,1,IF(G14-F14-D14>=2,0,)))))))) -> 0 | K14: Bahn 5 | L14: =C14 -> 17 | M14: =D14 -> 3 | O14: =INDEX(Basis!$C$2:$BJ$19,MATCH($C14,Basis!$B$2:$B$19,0),MATCH(O$4,Basis!$C$1:$BJ$1,0)) -> 1 | Q14: =IF(P14="",0,IF(P14-M14=0,2,IF(P14-M14=-1,3,IF(P14-M14=-2,4,IF(P14-M14=-3,5,IF(P14-M14=-4,6,IF(P14-M14=1,1,IF(P14-M14>=2,0,)))))))) -> 0 | R14: =IF(P14="",0,IF(P14-O14-M14=0,2,IF(P14-O14-M14=-1,3,IF(P14-O14-M14=-2,4,IF(P14-O14-M14=-3,5,IF(P14-O14-M14=-4,6,IF(P14-O14-M14=1,1,IF(P14-O14-M14>=2,0,)))))))) -> 0 | T14: Bahn 5 | U14: =C14 -> 17 | V14: =D14 -> 3 | X14: =INDEX(Basis!$C$2:$BJ$19,MATCH($U14,Basis!$B$2:$B$19,0),MATCH(X$4,Basis!$C$1:$BJ$1,0)) -> 1 | Z14: =IF(Y14="",0,IF(Y14-V14=0,2,IF(Y14-V14=-1,3,IF(Y14-V14=-2,4,IF(Y14-V14=-3,5,IF(Y14-V14=-4,6,IF(Y14-V14=1,1,IF(Y14-V14>=2,0,)))))))) -> 0 | AA14: =IF(Y14="",0,IF(Y14-X14-V14=0,2,IF(Y14-X14-V14=-1,3,IF(Y14-X14-V14=-2,4,IF(Y14-X14-V14=-3,5,IF(Y14-X14-V14=-4,6,IF(Y14-X14-V14=1,1,IF(Y14-X14-V14>=2,0,)))))))) -> 0 | AC14: =IF(AND(G14<P14,G14<Y14),2,0) -> 0 | AD14: =IF(AND(G14<P14,G14=Y14),1,0) -> 0 | AE14: =IF(AND(G14=P14,G14<Y14),1,0) -> 0 | AF14: =IF(AND(G14=P14,G14=Y14),1,0) -> 1 | AH14: =IF(AND(P14<G14,P14<Y14),2,0) -> 0 | AI14: =IF(AND(P14=G14,P14<Y14),1,0) -> 0 | AJ14: =IF(AND(P14=Y14,P14<G14),1,0) -> 0 | AK14: =IF(AND(P14=G14,P14=Y14),1,0) -> 1 | AM14: =IF(AND(Y14<G14,Y14<P14),2,0) -> 0 | AN14: =IF(AND(Y14=G14,Y14<P14),1,0) -> 0 | AO14: =IF(AND(Y14=P14,Y14<G14),1,0) -> 0 | AP14: =IF(AND(Y14=G14,Y14=P14),1,0) -> 1
B15: Bahn 6 | C15: 5 | D15: 4 | F15: =INDEX(Basis!$C$2:$BJ$19,MATCH($C15,Basis!$B$2:$B$19,0),MATCH(F$4,Basis!$C$1:$BJ$1,0)) -> 1 | H15: =IF(G15="",0,IF(G15-D15=0,2,IF(G15-D15=-1,3,IF(G15-D15=-2,4,IF(G15-D15=-3,5,IF(G15-D15=-4,6,IF(G15-D15=1,1,IF(G15-D15>=2,0,)))))))) -> 0 | I15: =IF(G15="",0,IF(G15-F15-D15=0,2,IF(G15-F15-D15=-1,3,IF(G15-F15-D15=-2,4,IF(G15-F15-D15=-3,5,IF(G15-F15-D15=-4,6,IF(G15-F15-D15=1,1,IF(G15-F15-D15>=2,0,)))))))) -> 0 | K15: Bahn 6 | L15: =C15 -> 5 | M15: =D15 -> 4 | O15: =INDEX(Basis!$C$2:$BJ$19,MATCH($C15,Basis!$B$2:$B$19,0),MATCH(O$4,Basis!$C$1:$BJ$1,0)) -> 2 | Q15: =IF(P15="",0,IF(P15-M15=0,2,IF(P15-M15=-1,3,IF(P15-M15=-2,4,IF(P15-M15=-3,5,IF(P15-M15=-4,6,IF(P15-M15=1,1,IF(P15-M15>=2,0,)))))))) -> 0 | R15: =IF(P15="",0,IF(P15-O15-M15=0,2,IF(P15-O15-M15=-1,3,IF(P15-O15-M15=-2,4,IF(P15-O15-M15=-3,5,IF(P15-O15-M15=-4,6,IF(P15-O15-M15=1,1,IF(P15-O15-M15>=2,0,)))))))) -> 0 | T15: Bahn 6 | U15: =C15 -> 5 | V15: =D15 -> 4 | X15: =INDEX(Basis!$C$2:$BJ$19,MATCH($U15,Basis!$B$2:$B$19,0),MATCH(X$4,Basis!$C$1:$BJ$1,0)) -> 2 | Z15: =IF(Y15="",0,IF(Y15-V15=0,2,IF(Y15-V15=-1,3,IF(Y15-V15=-2,4,IF(Y15-V15=-3,5,IF(Y15-V15=-4,6,IF(Y15-V15=1,1,IF(Y15-V15>=2,0,)))))))) -> 0 | AA15: =IF(Y15="",0,IF(Y15-X15-V15=0,2,IF(Y15-X15-V15=-1,3,IF(Y15-X15-V15=-2,4,IF(Y15-X15-V15=-3,5,IF(Y15-X15-V15=-4,6,IF(Y15-X15-V15=1,1,IF(Y15-X15-V15>=2,0,)))))))) -> 0 | AC15: =IF(AND(G15<P15,G15<Y15),2,0) -> 0 | AD15: =IF(AND(G15<P15,G15=Y15),1,0) -> 0 | AE15: =IF(AND(G15=P15,G15<Y15),1,0) -> 0 | AF15: =IF(AND(G15=P15,G15=Y15),1,0) -> 1 | AH15: =IF(AND(P15<G15,P15<Y15),2,0) -> 0 | AI15: =IF(AND(P15=G15,P15<Y15),1,0) -> 0 | AJ15: =IF(AND(P15=Y15,P15<G15),1,0) -> 0 | AK15: =IF(AND(P15=G15,P15=Y15),1,0) -> 1 | AM15: =IF(AND(Y15<G15,Y15<P15),2,0) -> 0 | AN15: =IF(AND(Y15=G15,Y15<P15),1,0) -> 0 | AO15: =IF(AND(Y15=P15,Y15<G15),1,0) -> 0 | AP15: =IF(AND(Y15=G15,Y15=P15),1,0) -> 1
B16: Bahn 7 | C16: 13 | D16: 4 | F16: =INDEX(Basis!$C$2:$BJ$19,MATCH($C16,Basis!$B$2:$B$19,0),MATCH(F$4,Basis!$C$1:$BJ$1,0)) -> 1 | H16: =IF(G16="",0,IF(G16-D16=0,2,IF(G16-D16=-1,3,IF(G16-D16=-2,4,IF(G16-D16=-3,5,IF(G16-D16=-4,6,IF(G16-D16=1,1,IF(G16-D16>=2,0,)))))))) -> 0 | I16: =IF(G16="",0,IF(G16-F16-D16=0,2,IF(G16-F16-D16=-1,3,IF(G16-F16-D16=-2,4,IF(G16-F16-D16=-3,5,IF(G16-F16-D16=-4,6,IF(G16-F16-D16=1,1,IF(G16-F16-D16>=2,0,)))))))) -> 0 | K16: Bahn 7 | L16: =C16 -> 13 | M16: =D16 -> 4 | O16: =INDEX(Basis!$C$2:$BJ$19,MATCH($C16,Basis!$B$2:$B$19,0),MATCH(O$4,Basis!$C$1:$BJ$1,0)) -> 1 | Q16: =IF(P16="",0,IF(P16-M16=0,2,IF(P16-M16=-1,3,IF(P16-M16=-2,4,IF(P16-M16=-3,5,IF(P16-M16=-4,6,IF(P16-M16=1,1,IF(P16-M16>=2,0,)))))))) -> 0 | R16: =IF(P16="",0,IF(P16-O16-M16=0,2,IF(P16-O16-M16=-1,3,IF(P16-O16-M16=-2,4,IF(P16-O16-M16=-3,5,IF(P16-O16-M16=-4,6,IF(P16-O16-M16=1,1,IF(P16-O16-M16>=2,0,)))))))) -> 0 | T16: Bahn 7 | U16: =C16 -> 13 | V16: =D16 -> 4 | X16: =INDEX(Basis!$C$2:$BJ$19,MATCH($U16,Basis!$B$2:$B$19,0),MATCH(X$4,Basis!$C$1:$BJ$1,0)) -> 1 | Z16: =IF(Y16="",0,IF(Y16-V16=0,2,IF(Y16-V16=-1,3,IF(Y16-V16=-2,4,IF(Y16-V16=-3,5,IF(Y16-V16=-4,6,IF(Y16-V16=1,1,IF(Y16-V16>=2,0,)))))))) -> 0 | AA16: =IF(Y16="",0,IF(Y16-X16-V16=0,2,IF(Y16-X16-V16=-1,3,IF(Y16-X16-V16=-2,4,IF(Y16-X16-V16=-3,5,IF(Y16-X16-V16=-4,6,IF(Y16-X16-V16=1,1,IF(Y16-X16-V16>=2,0,)))))))) -> 0 | AC16: =IF(AND(G16<P16,G16<Y16),2,0) -> 0 | AD16: =IF(AND(G16<P16,G16=Y16),1,0) -> 0 | AE16: =IF(AND(G16=P16,G16<Y16),1,0) -> 0 | AF16: =IF(AND(G16=P16,G16=Y16),1,0) -> 1 | AH16: =IF(AND(P16<G16,P16<Y16),2,0) -> 0 | AI16: =IF(AND(P16=G16,P16<Y16),1,0) -> 0 | AJ16: =IF(AND(P16=Y16,P16<G16),1,0) -> 0 | AK16: =IF(AND(P16=G16,P16=Y16),1,0) -> 1 | AM16: =IF(AND(Y16<G16,Y16<P16),2,0) -> 0 | AN16: =IF(AND(Y16=G16,Y16<P16),1,0) -> 0 | AO16: =IF(AND(Y16=P16,Y16<G16),1,0) -> 0 | AP16: =IF(AND(Y16=G16,Y16=P16),1,0) -> 1
B17: Bahn 8 | C17: 15 | D17: 3 | F17: =INDEX(Basis!$C$2:$BJ$19,MATCH($C17,Basis!$B$2:$B$19,0),MATCH(F$4,Basis!$C$1:$BJ$1,0)) -> 1 | H17: =IF(G17="",0,IF(G17-D17=0,2,IF(G17-D17=-1,3,IF(G17-D17=-2,4,IF(G17-D17=-3,5,IF(G17-D17=-4,6,IF(G17-D17=1,1,IF(G17-D17>=2,0,)))))))) -> 0 | I17: =IF(G17="",0,IF(G17-F17-D17=0,2,IF(G17-F17-D17=-1,3,IF(G17-F17-D17=-2,4,IF(G17-F17-D17=-3,5,IF(G17-F17-D17=-4,6,IF(G17-F17-D17=1,1,IF(G17-F17-D17>=2,0,)))))))) -> 0 | K17: Bahn 8 | L17: =C17 -> 15 | M17: =D17 -> 3 | O17: =INDEX(Basis!$C$2:$BJ$19,MATCH($C17,Basis!$B$2:$B$19,0),MATCH(O$4,Basis!$C$1:$BJ$1,0)) -> 1 | Q17: =IF(P17="",0,IF(P17-M17=0,2,IF(P17-M17=-1,3,IF(P17-M17=-2,4,IF(P17-M17=-3,5,IF(P17-M17=-4,6,IF(P17-M17=1,1,IF(P17-M17>=2,0,)))))))) -> 0 | R17: =IF(P17="",0,IF(P17-O17-M17=0,2,IF(P17-O17-M17=-1,3,IF(P17-O17-M17=-2,4,IF(P17-O17-M17=-3,5,IF(P17-O17-M17=-4,6,IF(P17-O17-M17=1,1,IF(P17-O17-M17>=2,0,)))))))) -> 0 | T17: Bahn 8 | U17: =C17 -> 15 | V17: =D17 -> 3 | X17: =INDEX(Basis!$C$2:$BJ$19,MATCH($U17,Basis!$B$2:$B$19,0),MATCH(X$4,Basis!$C$1:$BJ$1,0)) -> 1 | Z17: =IF(Y17="",0,IF(Y17-V17=0,2,IF(Y17-V17=-1,3,IF(Y17-V17=-2,4,IF(Y17-V17=-3,5,IF(Y17-V17=-4,6,IF(Y17-V17=1,1,IF(Y17-V17>=2,0,)))))))) -> 0 | AA17: =IF(Y17="",0,IF(Y17-X17-V17=0,2,IF(Y17-X17-V17=-1,3,IF(Y17-X17-V17=-2,4,IF(Y17-X17-V17=-3,5,IF(Y17-X17-V17=-4,6,IF(Y17-X17-V17=1,1,IF(Y17-X17-V17>=2,0,)))))))) -> 0 | AC17: =IF(AND(G17<P17,G17<Y17),2,0) -> 0 | AD17: =IF(AND(G17<P17,G17=Y17),1,0) -> 0 | AE17: =IF(AND(G17=P17,G17<Y17),1,0) -> 0 | AF17: =IF(AND(G17=P17,G17=Y17),1,0) -> 1 | AH17: =IF(AND(P17<G17,P17<Y17),2,0) -> 0 | AI17: =IF(AND(P17=G17,P17<Y17),1,0) -> 0 | AJ17: =IF(AND(P17=Y17,P17<G17),1,0) -> 0 | AK17: =IF(AND(P17=G17,P17=Y17),1,0) -> 1 | AM17: =IF(AND(Y17<G17,Y17<P17),2,0) -> 0 | AN17: =IF(AND(Y17=G17,Y17<P17),1,0) -> 0 | AO17: =IF(AND(Y17=P17,Y17<G17),1,0) -> 0 | AP17: =IF(AND(Y17=G17,Y17=P17),1,0) -> 1
B18: Bahn 9 | C18: 11 | D18: 4 | F18: =INDEX(Basis!$C$2:$BJ$19,MATCH($C18,Basis!$B$2:$B$19,0),MATCH(F$4,Basis!$C$1:$BJ$1,0)) -> 1 | H18: =IF(G18="",0,IF(G18-D18=0,2,IF(G18-D18=-1,3,IF(G18-D18=-2,4,IF(G18-D18=-3,5,IF(G18-D18=-4,6,IF(G18-D18=1,1,IF(G18-D18>=2,0,)))))))) -> 0 | I18: =IF(G18="",0,IF(G18-F18-D18=0,2,IF(G18-F18-D18=-1,3,IF(G18-F18-D18=-2,4,IF(G18-F18-D18=-3,5,IF(G18-F18-D18=-4,6,IF(G18-F18-D18=1,1,IF(G18-F18-D18>=2,0,)))))))) -> 0 | K18: Bahn 9 | L18: =C18 -> 11 | M18: =D18 -> 4 | O18: =INDEX(Basis!$C$2:$BJ$19,MATCH($C18,Basis!$B$2:$B$19,0),MATCH(O$4,Basis!$C$1:$BJ$1,0)) -> 1 | Q18: =IF(P18="",0,IF(P18-M18=0,2,IF(P18-M18=-1,3,IF(P18-M18=-2,4,IF(P18-M18=-3,5,IF(P18-M18=-4,6,IF(P18-M18=1,1,IF(P18-M18>=2,0,)))))))) -> 0 | R18: =IF(P18="",0,IF(P18-O18-M18=0,2,IF(P18-O18-M18=-1,3,IF(P18-O18-M18=-2,4,IF(P18-O18-M18=-3,5,IF(P18-O18-M18=-4,6,IF(P18-O18-M18=1,1,IF(P18-O18-M18>=2,0,)))))))) -> 0 | T18: Bahn 9 | U18: =C18 -> 11 | V18: =D18 -> 4 | X18: =INDEX(Basis!$C$2:$BJ$19,MATCH($U18,Basis!$B$2:$B$19,0),MATCH(X$4,Basis!$C$1:$BJ$1,0)) -> 1 | Z18: =IF(Y18="",0,IF(Y18-V18=0,2,IF(Y18-V18=-1,3,IF(Y18-V18=-2,4,IF(Y18-V18=-3,5,IF(Y18-V18=-4,6,IF(Y18-V18=1,1,IF(Y18-V18>=2,0,)))))))) -> 0 | AA18: =IF(Y18="",0,IF(Y18-X18-V18=0,2,IF(Y18-X18-V18=-1,3,IF(Y18-X18-V18=-2,4,IF(Y18-X18-V18=-3,5,IF(Y18-X18-V18=-4,6,IF(Y18-X18-V18=1,1,IF(Y18-X18-V18>=2,0,)))))))) -> 0 | AC18: =IF(AND(G18<P18,G18<Y18),2,0) -> 0 | AD18: =IF(AND(G18<P18,G18=Y18),1,0) -> 0 | AE18: =IF(AND(G18=P18,G18<Y18),1,0) -> 0 | AF18: =IF(AND(G18=P18,G18=Y18),1,0) -> 1 | AH18: =IF(AND(P18<G18,P18<Y18),2,0) -> 0 | AI18: =IF(AND(P18=G18,P18<Y18),1,0) -> 0 | AJ18: =IF(AND(P18=Y18,P18<G18),1,0) -> 0 | AK18: =IF(AND(P18=G18,P18=Y18),1,0) -> 1 | AM18: =IF(AND(Y18<G18,Y18<P18),2,0) -> 0 | AN18: =IF(AND(Y18=G18,Y18<P18),1,0) -> 0 | AO18: =IF(AND(Y18=P18,Y18<G18),1,0) -> 0 | AP18: =IF(AND(Y18=G18,Y18=P18),1,0) -> 1
B19: Bahn 10 | C19: 14 | D19: 3 | F19: =INDEX(Basis!$C$2:$BJ$19,MATCH($C19,Basis!$B$2:$B$19,0),MATCH(F$4,Basis!$C$1:$BJ$1,0)) -> 1 | H19: =IF(G19="",0,IF(G19-D19=0,2,IF(G19-D19=-1,3,IF(G19-D19=-2,4,IF(G19-D19=-3,5,IF(G19-D19=-4,6,IF(G19-D19=1,1,IF(G19-D19>=2,0,)))))))) -> 0 | I19: =IF(G19="",0,IF(G19-F19-D19=0,2,IF(G19-F19-D19=-1,3,IF(G19-F19-D19=-2,4,IF(G19-F19-D19=-3,5,IF(G19-F19-D19=-4,6,IF(G19-F19-D19=1,1,IF(G19-F19-D19>=2,0,)))))))) -> 0 | K19: Bahn 10 | L19: =C19 -> 14 | M19: =D19 -> 3 | O19: =INDEX(Basis!$C$2:$BJ$19,MATCH($C19,Basis!$B$2:$B$19,0),MATCH(O$4,Basis!$C$1:$BJ$1,0)) -> 1 | Q19: =IF(P19="",0,IF(P19-M19=0,2,IF(P19-M19=-1,3,IF(P19-M19=-2,4,IF(P19-M19=-3,5,IF(P19-M19=-4,6,IF(P19-M19=1,1,IF(P19-M19>=2,0,)))))))) -> 0 | R19: =IF(P19="",0,IF(P19-O19-M19=0,2,IF(P19-O19-M19=-1,3,IF(P19-O19-M19=-2,4,IF(P19-O19-M19=-3,5,IF(P19-O19-M19=-4,6,IF(P19-O19-M19=1,1,IF(P19-O19-M19>=2,0,)))))))) -> 0 | T19: Bahn 10 | U19: =C19 -> 14 | V19: =D19 -> 3 | X19: =INDEX(Basis!$C$2:$BJ$19,MATCH($U19,Basis!$B$2:$B$19,0),MATCH(X$4,Basis!$C$1:$BJ$1,0)) -> 1 | Z19: =IF(Y19="",0,IF(Y19-V19=0,2,IF(Y19-V19=-1,3,IF(Y19-V19=-2,4,IF(Y19-V19=-3,5,IF(Y19-V19=-4,6,IF(Y19-V19=1,1,IF(Y19-V19>=2,0,)))))))) -> 0 | AA19: =IF(Y19="",0,IF(Y19-X19-V19=0,2,IF(Y19-X19-V19=-1,3,IF(Y19-X19-V19=-2,4,IF(Y19-X19-V19=-3,5,IF(Y19-X19-V19=-4,6,IF(Y19-X19-V19=1,1,IF(Y19-X19-V19>=2,0,)))))))) -> 0 | AC19: =IF(AND(G19<P19,G19<Y19),2,0) -> 0 | AD19: =IF(AND(G19<P19,G19=Y19),1,0) -> 0 | AE19: =IF(AND(G19=P19,G19<Y19),1,0) -> 0 | AF19: =IF(AND(G19=P19,G19=Y19),1,0) -> 1 | AH19: =IF(AND(P19<G19,P19<Y19),2,0) -> 0 | AI19: =IF(AND(P19=G19,P19<Y19),1,0) -> 0 | AJ19: =IF(AND(P19=Y19,P19<G19),1,0) -> 0 | AK19: =IF(AND(P19=G19,P19=Y19),1,0) -> 1 | AM19: =IF(AND(Y19<G19,Y19<P19),2,0) -> 0 | AN19: =IF(AND(Y19=G19,Y19<P19),1,0) -> 0 | AO19: =IF(AND(Y19=P19,Y19<G19),1,0) -> 0 | AP19: =IF(AND(Y19=G19,Y19=P19),1,0) -> 1
B20: Bahn 11 | C20: 6 | D20: 4 | F20: =INDEX(Basis!$C$2:$BJ$19,MATCH($C20,Basis!$B$2:$B$19,0),MATCH(F$4,Basis!$C$1:$BJ$1,0)) -> 1 | H20: =IF(G20="",0,IF(G20-D20=0,2,IF(G20-D20=-1,3,IF(G20-D20=-2,4,IF(G20-D20=-3,5,IF(G20-D20=-4,6,IF(G20-D20=1,1,IF(G20-D20>=2,0,)))))))) -> 0 | I20: =IF(G20="",0,IF(G20-F20-D20=0,2,IF(G20-F20-D20=-1,3,IF(G20-F20-D20=-2,4,IF(G20-F20-D20=-3,5,IF(G20-F20-D20=-4,6,IF(G20-F20-D20=1,1,IF(G20-F20-D20>=2,0,)))))))) -> 0 | K20: Bahn 11 | L20: =C20 -> 6 | M20: =D20 -> 4 | O20: =INDEX(Basis!$C$2:$BJ$19,MATCH($C20,Basis!$B$2:$B$19,0),MATCH(O$4,Basis!$C$1:$BJ$1,0)) -> 2 | Q20: =IF(P20="",0,IF(P20-M20=0,2,IF(P20-M20=-1,3,IF(P20-M20=-2,4,IF(P20-M20=-3,5,IF(P20-M20=-4,6,IF(P20-M20=1,1,IF(P20-M20>=2,0,)))))))) -> 0 | R20: =IF(P20="",0,IF(P20-O20-M20=0,2,IF(P20-O20-M20=-1,3,IF(P20-O20-M20=-2,4,IF(P20-O20-M20=-3,5,IF(P20-O20-M20=-4,6,IF(P20-O20-M20=1,1,IF(P20-O20-M20>=2,0,)))))))) -> 0 | T20: Bahn 11 | U20: =C20 -> 6 | V20: =D20 -> 4 | X20: =INDEX(Basis!$C$2:$BJ$19,MATCH($U20,Basis!$B$2:$B$19,0),MATCH(X$4,Basis!$C$1:$BJ$1,0)) -> 2 | Z20: =IF(Y20="",0,IF(Y20-V20=0,2,IF(Y20-V20=-1,3,IF(Y20-V20=-2,4,IF(Y20-V20=-3,5,IF(Y20-V20=-4,6,IF(Y20-V20=1,1,IF(Y20-V20>=2,0,)))))))) -> 0 | AA20: =IF(Y20="",0,IF(Y20-X20-V20=0,2,IF(Y20-X20-V20=-1,3,IF(Y20-X20-V20=-2,4,IF(Y20-X20-V20=-3,5,IF(Y20-X20-V20=-4,6,IF(Y20-X20-V20=1,1,IF(Y20-X20-V20>=2,0,)))))))) -> 0 | AC20: =IF(AND(G20<P20,G20<Y20),2,0) -> 0 | AD20: =IF(AND(G20<P20,G20=Y20),1,0) -> 0 | AE20: =IF(AND(G20=P20,G20<Y20),1,0) -> 0 | AF20: =IF(AND(G20=P20,G20=Y20),1,0) -> 1 | AH20: =IF(AND(P20<G20,P20<Y20),2,0) -> 0 | AI20: =IF(AND(P20=G20,P20<Y20),1,0) -> 0 | AJ20: =IF(AND(P20=Y20,P20<G20),1,0) -> 0 | AK20: =IF(AND(P20=G20,P20=Y20),1,0) -> 1 | AM20: =IF(AND(Y20<G20,Y20<P20),2,0) -> 0 | AN20: =IF(AND(Y20=G20,Y20<P20),1,0) -> 0 | AO20: =IF(AND(Y20=P20,Y20<G20),1,0) -> 0 | AP20: =IF(AND(Y20=G20,Y20=P20),1,0) -> 1
B21: Bahn 12 | C21: 18 | D21: 3 | F21: =INDEX(Basis!$C$2:$BJ$19,MATCH($C21,Basis!$B$2:$B$19,0),MATCH(F$4,Basis!$C$1:$BJ$1,0)) -> 1 | H21: =IF(G21="",0,IF(G21-D21=0,2,IF(G21-D21=-1,3,IF(G21-D21=-2,4,IF(G21-D21=-3,5,IF(G21-D21=-4,6,IF(G21-D21=1,1,IF(G21-D21>=2,0,)))))))) -> 0 | I21: =IF(G21="",0,IF(G21-F21-D21=0,2,IF(G21-F21-D21=-1,3,IF(G21-F21-D21=-2,4,IF(G21-F21-D21=-3,5,IF(G21-F21-D21=-4,6,IF(G21-F21-D21=1,1,IF(G21-F21-D21>=2,0,)))))))) -> 0 | K21: Bahn 12 | L21: =C21 -> 18 | M21: =D21 -> 3 | O21: =INDEX(Basis!$C$2:$BJ$19,MATCH($C21,Basis!$B$2:$B$19,0),MATCH(O$4,Basis!$C$1:$BJ$1,0)) -> 1 | Q21: =IF(P21="",0,IF(P21-M21=0,2,IF(P21-M21=-1,3,IF(P21-M21=-2,4,IF(P21-M21=-3,5,IF(P21-M21=-4,6,IF(P21-M21=1,1,IF(P21-M21>=2,0,)))))))) -> 0 | R21: =IF(P21="",0,IF(P21-O21-M21=0,2,IF(P21-O21-M21=-1,3,IF(P21-O21-M21=-2,4,IF(P21-O21-M21=-3,5,IF(P21-O21-M21=-4,6,IF(P21-O21-M21=1,1,IF(P21-O21-M21>=2,0,)))))))) -> 0 | T21: Bahn 12 | U21: =C21 -> 18 | V21: =D21 -> 3 | X21: =INDEX(Basis!$C$2:$BJ$19,MATCH($U21,Basis!$B$2:$B$19,0),MATCH(X$4,Basis!$C$1:$BJ$1,0)) -> 1 | Z21: =IF(Y21="",0,IF(Y21-V21=0,2,IF(Y21-V21=-1,3,IF(Y21-V21=-2,4,IF(Y21-V21=-3,5,IF(Y21-V21=-4,6,IF(Y21-V21=1,1,IF(Y21-V21>=2,0,)))))))) -> 0 | AA21: =IF(Y21="",0,IF(Y21-X21-V21=0,2,IF(Y21-X21-V21=-1,3,IF(Y21-X21-V21=-2,4,IF(Y21-X21-V21=-3,5,IF(Y21-X21-V21=-4,6,IF(Y21-X21-V21=1,1,IF(Y21-X21-V21>=2,0,)))))))) -> 0 | AC21: =IF(AND(G21<P21,G21<Y21),2,0) -> 0 | AD21: =IF(AND(G21<P21,G21=Y21),1,0) -> 0 | AE21: =IF(AND(G21=P21,G21<Y21),1,0) -> 0 | AF21: =IF(AND(G21=P21,G21=Y21),1,0) -> 1 | AH21: =IF(AND(P21<G21,P21<Y21),2,0) -> 0 | AI21: =IF(AND(P21=G21,P21<Y21),1,0) -> 0 | AJ21: =IF(AND(P21=Y21,P21<G21),1,0) -> 0 | AK21: =IF(AND(P21=G21,P21=Y21),1,0) -> 1 | AM21: =IF(AND(Y21<G21,Y21<P21),2,0) -> 0 | AN21: =IF(AND(Y21=G21,Y21<P21),1,0) -> 0 | AO21: =IF(AND(Y21=P21,Y21<G21),1,0) -> 0 | AP21: =IF(AND(Y21=G21,Y21=P21),1,0) -> 1
... B27: Bahn 18 | C27: 10 | D27: 4 | F27: =INDEX(Basis!$C$2:$BJ$19,MATCH($C27,Basis!$B$2:$B$19,0),MATCH(F$4,Basis!$C$1:$BJ$1,0)) -> 1 | H27: =IF(G27="",0,IF(G27-D27=0,2,IF(G27-D27=-1,3,IF(G27-D27=-2,4,IF(G27-D27=-3,5,IF(G27-D27=-4,6,IF(G27-D27=1,1,IF(G27-D27>=2,0,)))))))) -> 0 | I27: =IF(G27="",0,IF(G27-F27-D27=0,2,IF(G27-F27-D27=-1,3,IF(G27-F27-D27=-2,4,IF(G27-F27-D27=-3,5,IF(G27-F27-D27=-4,6,IF(G27-F27-D27=1,1,IF(G27-F27-D27>=2,0,)))))))) -> 0 | K27: Bahn 18 | L27: =C27 -> 10 | M27: =D27 -> 4 | O27: =INDEX(Basis!$C$2:$BJ$19,MATCH($C27,Basis!$B$2:$B$19,0),MATCH(O$4,Basis!$C$1:$BJ$1,0)) -> 1 | Q27: =IF(P27="",0,IF(P27-M27=0,2,IF(P27-M27=-1,3,IF(P27-M27=-2,4,IF(P27-M27=-3,5,IF(P27-M27=-4,6,IF(P27-M27=1,1,IF(P27-M27>=2,0,)))))))) -> 0 | R27: =IF(P27="",0,IF(P27-O27-M27=0,2,IF(P27-O27-M27=-1,3,IF(P27-O27-M27=-2,4,IF(P27-O27-M27=-3,5,IF(P27-O27-M27=-4,6,IF(P27-O27-M27=1,1,IF(P27-O27-M27>=2,0,)))))))) -> 0 | T27: Bahn 18 | U27: =C27 -> 10 | V27: =D27 -> 4 | X27: =INDEX(Basis!$C$2:$BJ$19,MATCH($U27,Basis!$B$2:$B$19,0),MATCH(X$4,Basis!$C$1:$BJ$1,0)) -> 1 | Z27: =IF(Y27="",0,IF(Y27-V27=0,2,IF(Y27-V27=-1,3,IF(Y27-V27=-2,4,IF(Y27-V27=-3,5,IF(Y27-V27=-4,6,IF(Y27-V27=1,1,IF(Y27-V27>=2,0,)))))))) -> 0 | AA27: =IF(Y27="",0,IF(Y27-X27-V27=0,2,IF(Y27-X27-V27=-1,3,IF(Y27-X27-V27=-2,4,IF(Y27-X27-V27=-3,5,IF(Y27-X27-V27=-4,6,IF(Y27-X27-V27=1,1,IF(Y27-X27-V27>=2,0,)))))))) -> 0 | AC27: =IF(AND(G27<P27,G27<Y27),2,0) -> 0 | AD27: =IF(AND(G27<P27,G27=Y27),1,0) -> 0 | AE27: =IF(AND(G27=P27,G27<Y27),1,0) -> 0 | AF27: =IF(AND(G27=P27,G27=Y27),1,0) -> 1 | AH27: =IF(AND(P27<G27,P27<Y27),2,0) -> 0 | AI27: =IF(AND(P27=G27,P27<Y27),1,0) -> 0 | AJ27: =IF(AND(P27=Y27,P27<G27),1,0) -> 0 | AK27: =IF(AND(P27=G27,P27=Y27),1,0) -> 1 | AM27: =IF(AND(Y27<G27,Y27<P27),2,0) -> 0 | AN27: =IF(AND(Y27=G27,Y27<P27),1,0) -> 0 | AO27: =IF(AND(Y27=P27,Y27<G27),1,0) -> 0 | AP27: =IF(AND(Y27=G27,Y27=P27),1,0) -> 1
B29: In | G29: =SUM(G10:G18) -> 0 | H29: =SUM(H10:H18) -> 0 | I29: =SUM(I10:I18) -> 0 | K29: In | P29: =SUM(P10:P18) -> 0 | Q29: =SUM(Q10:Q18) -> 0 | R29: =SUM(R10:R18) -> 0 | T29: In | Y29: =SUM(Y10:Y18) -> 0 | Z29: =SUM(Z10:Z18) -> 0 | AA29: =SUM(AA10:AA18) -> 0 | AC29: =SUM(AC10:AC18) -> 0 | AD29: =SUM(AD10:AD18) -> 0 | AE29: =SUM(AE10:AE18) -> 0 | AF29: =SUM(AF10:AF18) -> 9 | AH29: =SUM(AH10:AH18) -> 0 | AI29: =SUM(AI10:AI18) -> 0 | AJ29: =SUM(AJ10:AJ18) -> 0 | AK29: =SUM(AK10:AK18) -> 9 | AM29: =SUM(AM10:AM18) -> 0 | AN29: =SUM(AN10:AN18) -> 0 | AO29: =SUM(AO10:AO18) -> 0 | AP29: =SUM(AP10:AP18) -> 9
B30: Out | G30: =SUM(G19:G27) -> 0 | H30: =SUM(H19:H27) -> 0 | I30: =SUM(I19:I27) -> 0 | K30: Out | P30: =SUM(P19:P27) -> 0 | Q30: =SUM(Q19:Q27) -> 0 | R30: =SUM(R19:R27) -> 0 | T30: Out | Y30: =SUM(Y19:Y27) -> 0 | Z30: =SUM(Z19:Z27) -> 0 | AA30: =SUM(AA19:AA27) -> 0 | AC30: =SUM(AC19:AC27) -> 0 | AD30: =SUM(AD19:AD27) -> 0 | AE30: =SUM(AE19:AE27) -> 0 | AF30: =SUM(AF19:AF27) -> 9 | AH30: =SUM(AH19:AH27) -> 0 | AI30: =SUM(AI19:AI27) -> 0 | AJ30: =SUM(AJ19:AJ27) -> 0 | AK30: =SUM(AK19:AK27) -> 9 | AM30: =SUM(AM19:AM27) -> 0 | AN30: =SUM(AN19:AN27) -> 0 | AO30: =SUM(AO19:AO27) -> 0 | AP30: =SUM(AP19:AP27) -> 9
F31: =SUM(F10:F27) -> 19 | G31: =SUM(G10:G27) -> 0 | H31: =SUM(H10:H27) -> 0 | I31: =SUM(I10:I27) -> 0 | O31: =SUM(O10:O27) -> 24 | P31: =SUM(P10:P27) -> 0 | Q31: =SUM(Q10:Q27) -> 0 | R31: =SUM(R10:R27) -> 0 | X31: =SUM(X10:X27) -> 26 | Y31: =SUM(Y10:Y27) -> 0 | Z31: =SUM(Z10:Z27) -> 0 | AA31: =SUM(AA10:AA27) -> 0 | AC31: =SUM(AC10:AC27) -> 0 | AD31: =SUM(AD10:AD27) -> 0 | AE31: =SUM(AE10:AE27) -> 0 | AF31: =SUM(AF10:AF27) -> 18 | AH31: =SUM(AH10:AH27) -> 0 | AI31: =SUM(AI10:AI27) -> 0 | AJ31: =SUM(AJ10:AJ27) -> 0 | AK31: =SUM(AK10:AK27) -> 18 | AM31: =SUM(AM10:AM27) -> 0 | AN31: =SUM(AN10:AN27) -> 0 | AO31: =SUM(AO10:AO27) -> 0 | AP31: =SUM(AP10:AP27) -> 18
AF32: =SUM(AC31:AF31) -> 18 | AK32: =SUM(AH31:AK31) -> 18 | AP32: =SUM(AM31:AP31) -> 18
B34: GC Bad Waltersdorf
A35: Spieler | B35: Ludwig | K35: Andreas | T35: Peter | AC35: =B35 -> Ludwig | AH35: =K35 -> Andreas | AM35: =T35 -> Peter
A36: HCP | F36: =F3 -> 17.4 | O36: =O3 -> 21.3 | X36: =X3 -> 26.3
A37: Spielvorgabe | F37: 17 | O37: 21 | X37: 27
A38: Vorgabeklasse | F38: =IF(F36<4.4,1,IF(AND(F36>=4.5,F36<=11.4),2,IF(AND(F36>=11.5,F36<=18.4),3,IF(AND(F36>=18.5,F36<=26.4),4,IF(AND(F36>=26.5,F36<=36),5,IF(F36>=36,6)))))) -> 3 | O38: =IF(O36<4.4,1,IF(AND(O36>=4.5,O36<=11.4),2,IF(AND(O36>=11.5,O36<=18.4),3,IF(AND(O36>=18.5,O36<=26.4),4,IF(AND(O36>=26.5,O36<=36),5,IF(O36>=36,6)))))) -> 4 | X38: =IF(X36<4.4,1,IF(AND(X36>=4.5,X36<=11.4),2,IF(AND(X36>=11.5,X36<=18.4),3,IF(AND(X36>=18.5,X36<=26.4),4,IF(AND(X36>=26.5,X36<=36),5,IF(X36>=36,6)))))) -> 4
A39: Pufferzone | F39: =VLOOKUP(F38,HCP!$A$6:$C$11,3,FALSE) -> 33 | O39: =VLOOKUP(O38,HCP!$A$6:$C$11,3,FALSE) -> 32 | X39: =VLOOKUP(X38,HCP!$A$6:$C$11,3,FALSE) -> 32
F40: =IF(I64>36,"Herabsetzung",IF(AND(I64<=36,I64>=F39),"Puffer","Heraufsetzung")) -> Heraufsetzung | O40: =IF(R64>36,"Herabsetzung",IF(AND(R64<=36,R64>=O39),"Puffer","Heraufsetzung")) -> Heraufsetzung | X40: =IF(AA64>36,"Herabsetzung",IF(AND(AA64<=36,AA64>=X39),"Puffer","Heraufsetzung")) -> Heraufsetzung
A41: Neues HCP | F41: =IF(F40="Heraufsetzung",INDEX(HCP!$C$395:$D$755,MATCH(F36,HCP!$C$394:$C$755,0),MATCH($A$8,HCP!$D$394,0)),IF(F40="Puffer",F36,IF(F40="Herabsetzung",INDEX(HCP!$C$29:$AK$389,MATCH(F36,HCP!$C$29:$C$389,0),MATCH(I64,HCP!$C$28:$AK$28,0))))) -> 17.5 | O41: =IF(O40="Heraufsetzung",INDEX(HCP!$C$395:$D$755,MATCH(O36,HCP!$C$394:$C$755,0),MATCH($A$8,HCP!$D$394,0)),IF(O40="Puffer",O36,IF(O40="Herabsetzung",INDEX(HCP!$C$29:$AK$389,MATCH(O36,HCP!$C$29:$C$389,0),MATCH(R64,HCP!$C$28:$AK$28,0))))) -> 21.4 | X41: =IF(X40="Heraufsetzung",INDEX(HCP!$C$395:$D$755,MATCH(X36,HCP!$C$394:$C$755,0),MATCH($A$8,HCP!$D$394,0)),IF(X40="Puffer",X36,IF(X40="Herabsetzung",INDEX(HCP!$C$29:$AK$389,MATCH(X36,HCP!$C$29:$C$389,0),MATCH(AA64,HCP!$C$28:$AK$28,0))))) -> 26.4
C42: HCP | D42: PAR | F42: Spv | G42: Schläge | H42: Brutto | I42: Netto | L42: HCP | M42: PAR | O42: Spv | P42: Schläge | Q42: Brutto | R42: Netto | U42: HCP | V42: PAR | X42: Spv | Y42: Schläge | Z42: Brutto | AA42: Netto | AC42: Allein | AD42: Zwei | AE42: Zwei | AF42: Drei | AH42: Allein | AI42: Zwei | AJ42: Zwei | AK42: Drei | AM42: Allein | AN42: Zwei | AO42: Zwei | AP42: Drei
B43: Bahn 1 | C43: 9 | D43: 4 | F43: =INDEX(Basis!$C$2:$BJ$19,MATCH($C43,Basis!$B$2:$B$19,0),MATCH(F$37,Basis!$C$1:$BJ$1,0)) -> 1 | H43: =IF(G43="",0,IF(G43-D43=0,2,IF(G43-D43=-1,3,IF(G43-D43=-2,4,IF(G43-D43=-3,5,IF(G43-D43=-4,6,IF(G43-D43=1,1,IF(G43-D43>=2,0,)))))))) -> 0 | I43: =IF(G43="",0,IF(G43-F43-D43=0,2,IF(G43-F43-D43=-1,3,IF(G43-F43-D43=-2,4,IF(G43-F43-D43=-3,5,IF(G43-F43-D43=-4,6,IF(G43-F43-D43=1,1,IF(G43-F43-D43>=2,0,)))))))) -> 0 | K43: Bahn 1 | L43: =C43 -> 9 | M43: =D43 -> 4 | O43: =INDEX(Basis!$C$2:$BJ$19,MATCH($C43,Basis!$B$2:$B$19,0),MATCH(O$37,Basis!$C$1:$BJ$1,0)) -> 1 | Q43: =IF(P43="",0,IF(P43-M43=0,2,IF(P43-M43=-1,3,IF(P43-M43=-2,4,IF(P43-M43=-3,5,IF(P43-M43=-4,6,IF(P43-M43=1,1,IF(P43-M43>=2,0,)))))))) -> 0 | R43: =IF(P43="",0,IF(P43-O43-M43=0,2,IF(P43-O43-M43=-1,3,IF(P43-O43-M43=-2,4,IF(P43-O43-M43=-3,5,IF(P43-O43-M43=-4,6,IF(P43-O43-M43=1,1,IF(P43-O43-M43>=2,0,)))))))) -> 0 | T43: Bahn 1 | U43: =C43 -> 9 | V43: =D43 -> 4 | X43: =INDEX(Basis!$C$2:$BJ$19,MATCH($U43,Basis!$B$2:$B$19,0),MATCH(X$37,Basis!$C$1:$BJ$1,0)) -> 2 | Z43: =IF(Y43="",0,IF(Y43-V43=0,2,IF(Y43-V43=-1,3,IF(Y43-V43=-2,4,IF(Y43-V43=-3,5,IF(Y43-V43=-4,6,IF(Y43-V43=1,1,IF(Y43-V43>=2,0,)))))))) -> 0 | AA43: =IF(Y43="",0,IF(Y43-X43-V43=0,2,IF(Y43-X43-V43=-1,3,IF(Y43-X43-V43=-2,4,IF(Y43-X43-V43=-3,5,IF(Y43-X43-V43=-4,6,IF(Y43-X43-V43=1,1,IF(Y43-X43-V43>=2,0,)))))))) -> 0 | AC43: =IF(AND(G43<P43,G43<Y43),2,0) -> 0 | AD43: =IF(AND(G43<P43,G43=Y43),1,0) -> 0 | AE43: =IF(AND(G43=P43,G43<Y43),1,0) -> 0 | AF43: =IF(AND(G43=P43,G43=Y43),1,0) -> 1 | AH43: =IF(AND(P43<G43,P43<Y43),2,0) -> 0 | AI43: =IF(AND(P43=G43,P43<Y43),1,0) -> 0 | AJ43: =IF(AND(P43=Y43,P43<G43),1,0) -> 0 | AK43: =IF(AND(P43=G43,P43=Y43),1,0) -> 1 | AM43: =IF(AND(Y43<G43,Y43<P43),2,0) -> 0 | AN43: =IF(AND(Y43=G43,Y43<P43),1,0) -> 0 | AO43: =IF(AND(Y43=P43,Y43<G43),1,0) -> 0 | AP43: =IF(AND(Y43=G43,Y43=P43),1,0) -> 1
B44: Bahn 2 | C44: 3 | D44: 5 | F44: =INDEX(Basis!$C$2:$BJ$19,MATCH($C44,Basis!$B$2:$B$19,0),MATCH(F$37,Basis!$C$1:$BJ$1,0)) -> 1 | H44: =IF(G44="",0,IF(G44-D44=0,2,IF(G44-D44=-1,3,IF(G44-D44=-2,4,IF(G44-D44=-3,5,IF(G44-D44=-4,6,IF(G44-D44=1,1,IF(G44-D44>=2,0,)))))))) -> 0 | I44: =IF(G44="",0,IF(G44-F44-D44=0,2,IF(G44-F44-D44=-1,3,IF(G44-F44-D44=-2,4,IF(G44-F44-D44=-3,5,IF(G44-F44-D44=-4,6,IF(G44-F44-D44=1,1,IF(G44-F44-D44>=2,0,)))))))) -> 0 | K44: Bahn 2 | L44: =C44 -> 3 | M44: =D44 -> 5 | O44: =INDEX(Basis!$C$2:$BJ$19,MATCH($C44,Basis!$B$2:$B$19,0),MATCH(O$37,Basis!$C$1:$BJ$1,0)) -> 2 | Q44: =IF(P44="",0,IF(P44-M44=0,2,IF(P44-M44=-1,3,IF(P44-M44=-2,4,IF(P44-M44=-3,5,IF(P44-M44=-4,6,IF(P44-M44=1,1,IF(P44-M44>=2,0,)))))))) -> 0 | R44: =IF(P44="",0,IF(P44-O44-M44=0,2,IF(P44-O44-M44=-1,3,IF(P44-O44-M44=-2,4,IF(P44-O44-M44=-3,5,IF(P44-O44-M44=-4,6,IF(P44-O44-M44=1,1,IF(P44-O44-M44>=2,0,)))))))) -> 0 | T44: Bahn 2 | U44: =C44 -> 3 | V44: =D44 -> 5 | X44: =INDEX(Basis!$C$2:$BJ$19,MATCH($U44,Basis!$B$2:$B$19,0),MATCH(X$37,Basis!$C$1:$BJ$1,0)) -> 2 | Z44: =IF(Y44="",0,IF(Y44-V44=0,2,IF(Y44-V44=-1,3,IF(Y44-V44=-2,4,IF(Y44-V44=-3,5,IF(Y44-V44=-4,6,IF(Y44-V44=1,1,IF(Y44-V44>=2,0,)))))))) -> 0 | AA44: =IF(Y44="",0,IF(Y44-X44-V44=0,2,IF(Y44-X44-V44=-1,3,IF(Y44-X44-V44=-2,4,IF(Y44-X44-V44=-3,5,IF(Y44-X44-V44=-4,6,IF(Y44-X44-V44=1,1,IF(Y44-X44-V44>=2,0,)))))))) -> 0 | AC44: =IF(AND(G44<P44,G44<Y44),2,0) -> 0 | AD44: =IF(AND(G44<P44,G44=Y44),1,0) -> 0 | AE44: =IF(AND(G44=P44,G44<Y44),1,0) -> 0 | AF44: =IF(AND(G44=P44,G44=Y44),1,0) -> 1 | AH44: =IF(AND(P44<G44,P44<Y44),2,0) -> 0 | AI44: =IF(AND(P44=G44,P44<Y44),1,0) -> 0 | AJ44: =IF(AND(P44=Y44,P44<G44),1,0) -> 0 | AK44: =IF(AND(P44=G44,P44=Y44),1,0) -> 1 | AM44: =IF(AND(Y44<G44,Y44<P44),2,0) -> 0 | AN44: =IF(AND(Y44=G44,Y44<P44),1,0) -> 0 | AO44: =IF(AND(Y44=P44,Y44<G44),1,0) -> 0 | AP44: =IF(AND(Y44=G44,Y44=P44),1,0) -> 1
B45: Bahn 3 | C45: 1 | D45: 4 | F45: =INDEX(Basis!$C$2:$BJ$19,MATCH($C45,Basis!$B$2:$B$19,0),MATCH(F$37,Basis!$C$1:$BJ$1,0)) -> 1 | H45: =IF(G45="",0,IF(G45-D45=0,2,IF(G45-D45=-1,3,IF(G45-D45=-2,4,IF(G45-D45=-3,5,IF(G45-D45=-4,6,IF(G45-D45=1,1,IF(G45-D45>=2,0,)))))))) -> 0 | I45: =IF(G45="",0,IF(G45-F45-D45=0,2,IF(G45-F45-D45=-1,3,IF(G45-F45-D45=-2,4,IF(G45-F45-D45=-3,5,IF(G45-F45-D45=-4,6,IF(G45-F45-D45=1,1,IF(G45-F45-D45>=2,0,)))))))) -> 0 | K45: Bahn 3 | L45: =C45 -> 1 | M45: =D45 -> 4 | O45: =INDEX(Basis!$C$2:$BJ$19,MATCH($C45,Basis!$B$2:$B$19,0),MATCH(O$37,Basis!$C$1:$BJ$1,0)) -> 2 | Q45: =IF(P45="",0,IF(P45-M45=0,2,IF(P45-M45=-1,3,IF(P45-M45=-2,4,IF(P45-M45=-3,5,IF(P45-M45=-4,6,IF(P45-M45=1,1,IF(P45-M45>=2,0,)))))))) -> 0 | R45: =IF(P45="",0,IF(P45-O45-M45=0,2,IF(P45-O45-M45=-1,3,IF(P45-O45-M45=-2,4,IF(P45-O45-M45=-3,5,IF(P45-O45-M45=-4,6,IF(P45-O45-M45=1,1,IF(P45-O45-M45>=2,0,)))))))) -> 0 | T45: Bahn 3 | U45: =C45 -> 1 | V45: =D45 -> 4 | X45: =INDEX(Basis!$C$2:$BJ$19,MATCH($U45,Basis!$B$2:$B$19,0),MATCH(X$37,Basis!$C$1:$BJ$1,0)) -> 2 | Z45: =IF(Y45="",0,IF(Y45-V45=0,2,IF(Y45-V45=-1,3,IF(Y45-V45=-2,4,IF(Y45-V45=-3,5,IF(Y45-V45=-4,6,IF(Y45-V45=1,1,IF(Y45-V45>=2,0,)))))))) -> 0 | AA45: =IF(Y45="",0,IF(Y45-X45-V45=0,2,IF(Y45-X45-V45=-1,3,IF(Y45-X45-V45=-2,4,IF(Y45-X45-V45=-3,5,IF(Y45-X45-V45=-4,6,IF(Y45-X45-V45=1,1,IF(Y45-X45-V45>=2,0,)))))))) -> 0 | AC45: =IF(AND(G45<P45,G45<Y45),2,0) -> 0 | AD45: =IF(AND(G45<P45,G45=Y45),1,0) -> 0 | AE45: =IF(AND(G45=P45,G45<Y45),1,0) -> 0 | AF45: =IF(AND(G45=P45,G45=Y45),1,0) -> 1 | AH45: =IF(AND(P45<G45,P45<Y45),2,0) -> 0 | AI45: =IF(AND(P45=G45,P45<Y45),1,0) -> 0 | AJ45: =IF(AND(P45=Y45,P45<G45),1,0) -> 0 | AK45: =IF(AND(P45=G45,P45=Y45),1,0) -> 1 | AM45: =IF(AND(Y45<G45,Y45<P45),2,0) -> 0 | AN45: =IF(AND(Y45=G45,Y45<P45),1,0) -> 0 | AO45: =IF(AND(Y45=P45,Y45<G45),1,0) -> 0 | AP45: =IF(AND(Y45=G45,Y45=P45),1,0) -> 1
B46: Bahn 4 | C46: 13 | D46: 3 | F46: =INDEX(Basis!$C$2:$BJ$19,MATCH($C46,Basis!$B$2:$B$19,0),MATCH(F$37,Basis!$C$1:$BJ$1,0)) -> 1 | H46: =IF(G46="",0,IF(G46-D46=0,2,IF(G46-D46=-1,3,IF(G46-D46=-2,4,IF(G46-D46=-3,5,IF(G46-D46=-4,6,IF(G46-D46=1,1,IF(G46-D46>=2,0,)))))))) -> 0 | I46: =IF(G46="",0,IF(G46-F46-D46=0,2,IF(G46-F46-D46=-1,3,IF(G46-F46-D46=-2,4,IF(G46-F46-D46=-3,5,IF(G46-F46-D46=-4,6,IF(G46-F46-D46=1,1,IF(G46-F46-D46>=2,0,)))))))) -> 0 | K46: Bahn 4 | L46: =C46 -> 13 | M46: =D46 -> 3 | O46: =INDEX(Basis!$C$2:$BJ$19,MATCH($C46,Basis!$B$2:$B$19,0),MATCH(O$37,Basis!$C$1:$BJ$1,0)) -> 1 | Q46: =IF(P46="",0,IF(P46-M46=0,2,IF(P46-M46=-1,3,IF(P46-M46=-2,4,IF(P46-M46=-3,5,IF(P46-M46=-4,6,IF(P46-M46=1,1,IF(P46-M46>=2,0,)))))))) -> 0 | R46: =IF(P46="",0,IF(P46-O46-M46=0,2,IF(P46-O46-M46=-1,3,IF(P46-O46-M46=-2,4,IF(P46-O46-M46=-3,5,IF(P46-O46-M46=-4,6,IF(P46-O46-M46=1,1,IF(P46-O46-M46>=2,0,)))))))) -> 0 | T46: Bahn 4 | U46: =C46 -> 13 | V46: =D46 -> 3 | X46: =INDEX(Basis!$C$2:$BJ$19,MATCH($U46,Basis!$B$2:$B$19,0),MATCH(X$37,Basis!$C$1:$BJ$1,0)) -> 1 | Z46: =IF(Y46="",0,IF(Y46-V46=0,2,IF(Y46-V46=-1,3,IF(Y46-V46=-2,4,IF(Y46-V46=-3,5,IF(Y46-V46=-4,6,IF(Y46-V46=1,1,IF(Y46-V46>=2,0,)))))))) -> 0 | AA46: =IF(Y46="",0,IF(Y46-X46-V46=0,2,IF(Y46-X46-V46=-1,3,IF(Y46-X46-V46=-2,4,IF(Y46-X46-V46=-3,5,IF(Y46-X46-V46=-4,6,IF(Y46-X46-V46=1,1,IF(Y46-X46-V46>=2,0,)))))))) -> 0 | AC46: =IF(AND(G46<P46,G46<Y46),2,0) -> 0 | AD46: =IF(AND(G46<P46,G46=Y46),1,0) -> 0 | AE46: =IF(AND(G46=P46,G46<Y46),1,0) -> 0 | AF46: =IF(AND(G46=P46,G46=Y46),1,0) -> 1 | AH46: =IF(AND(P46<G46,P46<Y46),2,0) -> 0 | AI46: =IF(AND(P46=G46,P46<Y46),1,0) -> 0 | AJ46: =IF(AND(P46=Y46,P46<G46),1,0) -> 0 | AK46: =IF(AND(P46=G46,P46=Y46),1,0) -> 1 | AM46: =IF(AND(Y46<G46,Y46<P46),2,0) -> 0 | AN46: =IF(AND(Y46=G46,Y46<P46),1,0) -> 0 | AO46: =IF(AND(Y46=P46,Y46<G46),1,0) -> 0 | AP46: =IF(AND(Y46=G46,Y46=P46),1,0) -> 1
B47: Bahn 5 | C47: 11 | D47: 4 | F47: =INDEX(Basis!$C$2:$BJ$19,MATCH($C47,Basis!$B$2:$B$19,0),MATCH(F$37,Basis!$C$1:$BJ$1,0)) -> 1 | H47: =IF(G47="",0,IF(G47-D47=0,2,IF(G47-D47=-1,3,IF(G47-D47=-2,4,IF(G47-D47=-3,5,IF(G47-D47=-4,6,IF(G47-D47=1,1,IF(G47-D47>=2,0,)))))))) -> 0 | I47: =IF(G47="",0,IF(G47-F47-D47=0,2,IF(G47-F47-D47=-1,3,IF(G47-F47-D47=-2,4,IF(G47-F47-D47=-3,5,IF(G47-F47-D47=-4,6,IF(G47-F47-D47=1,1,IF(G47-F47-D47>=2,0,)))))))) -> 0 | K47: Bahn 5 | L47: =C47 -> 11 | M47: =D47 -> 4 | O47: =INDEX(Basis!$C$2:$BJ$19,MATCH($C47,Basis!$B$2:$B$19,0),MATCH(O$37,Basis!$C$1:$BJ$1,0)) -> 1 | Q47: =IF(P47="",0,IF(P47-M47=0,2,IF(P47-M47=-1,3,IF(P47-M47=-2,4,IF(P47-M47=-3,5,IF(P47-M47=-4,6,IF(P47-M47=1,1,IF(P47-M47>=2,0,)))))))) -> 0 | R47: =IF(P47="",0,IF(P47-O47-M47=0,2,IF(P47-O47-M47=-1,3,IF(P47-O47-M47=-2,4,IF(P47-O47-M47=-3,5,IF(P47-O47-M47=-4,6,IF(P47-O47-M47=1,1,IF(P47-O47-M47>=2,0,)))))))) -> 0 | T47: Bahn 5 | U47: =C47 -> 11 | V47: =D47 -> 4 | X47: =INDEX(Basis!$C$2:$BJ$19,MATCH($U47,Basis!$B$2:$B$19,0),MATCH(X$37,Basis!$C$1:$BJ$1,0)) -> 1 | Z47: =IF(Y47="",0,IF(Y47-V47=0,2,IF(Y47-V47=-1,3,IF(Y47-V47=-2,4,IF(Y47-V47=-3,5,IF(Y47-V47=-4,6,IF(Y47-V47=1,1,IF(Y47-V47>=2,0,)))))))) -> 0 | AA47: =IF(Y47="",0,IF(Y47-X47-V47=0,2,IF(Y47-X47-V47=-1,3,IF(Y47-X47-V47=-2,4,IF(Y47-X47-V47=-3,5,IF(Y47-X47-V47=-4,6,IF(Y47-X47-V47=1,1,IF(Y47-X47-V47>=2,0,)))))))) -> 0 | AC47: =IF(AND(G47<P47,G47<Y47),2,0) -> 0 | AD47: =IF(AND(G47<P47,G47=Y47),1,0) -> 0 | AE47: =IF(AND(G47=P47,G47<Y47),1,0) -> 0 | AF47: =IF(AND(G47=P47,G47=Y47),1,0) -> 1 | AH47: =IF(AND(P47<G47,P47<Y47),2,0) -> 0 | AI47: =IF(AND(P47=G47,P47<Y47),1,0) -> 0 | AJ47: =IF(AND(P47=Y47,P47<G47),1,0) -> 0 | AK47: =IF(AND(P47=G47,P47=Y47),1,0) -> 1 | AM47: =IF(AND(Y47<G47,Y47<P47),2,0) -> 0 | AN47: =IF(AND(Y47=G47,Y47<P47),1,0) -> 0 | AO47: =IF(AND(Y47=P47,Y47<G47),1,0) -> 0 | AP47: =IF(AND(Y47=G47,Y47=P47),1,0) -> 1
...

Sheet Basis
B1: Spielvorgabe | C1: 1 | D1: 2 | E1: 3 | F1: 4 | G1: 5 | H1: 6 | I1: 7 | J1: 8 | K1: 9 | L1: 10 | M1: 11 | N1: 12 | O1: 13 | P1: 14 | Q1: 15 | R1: 16 | S1: 17 | T1: 18 | U1: 19 | V1: 20 | W1: 21 | X1: 22 | Y1: 23 | Z1: 24 | AA1: 25 | AB1: 26 | AC1: 27 | AD1: 28 | AE1: 29 | AF1: 30 | AG1: 31 | AH1: 32 | AI1: 33 | AJ1: 34 | AK1: 35 | AL1: 36 | AM1: 37 | AN1: 38 | AO1: 39 | AP1: 40 | AQ1: 41 | AR1: 42 | AS1: 43 | AT1: 44 | AU1: 45 | AV1: 46 | AW1: 47 | AX1: 48 | AY1: 49 | AZ1: 50 | BA1: 51 | BB1: 52 | BC1: 53 | BD1: 54 | BE1: 55 | BF1: 56 | BG1: 57 | BH1: 58 | BI1: 59 | BJ1: 60
A2: HCP 1 | B2: 1 | C2: 1 | D2: 1 | E2: 1 | F2: 1 | G2: 1 | H2: 1 | I2: 1 | J2: 1 | K2: 1 | L2: 1 | M2: 1 | N2: 1 | O2: 1 | P2: 1 | Q2: 1 | R2: 1 | S2: 1 | T2: 1 | U2: 2 | V2: 2 | W2: 2 | X2: 2 | Y2: 2 | Z2: 2 | AA2: 2 | AB2: 2 | AC2: 2 | AD2: 2 | AE2: 2 | AF2: 2 | AG2: 2 | AH2: 2 | AI2: 2 | AJ2: 2 | AK2: 2 | AL2: 2 | AM2: 3 | AN2: 3 | AO2: 3 | AP2: 3 | AQ2: 3 | AR2: 3 | AS2: 3 | AT2: 3 | AU2: 3 | AV2: 3 | AW2: 3 | AX2: 3 | AY2: 3 | AZ2: 3 | BA2: 3 | BB2: 3 | BC2: 3 | BD2: 3 | BE2: 4 | BF2: 4 | BG2: 4 | BH2: 4 | BI2: 4 | BJ2: 4
A3: HCP 2 | B3: 2 | D3: 1 | E3: 1 | F3: 1 | G3: 1 | H3: 1 | I3: 1 | J3: 1 | K3: 1 | L3: 1 | M3: 1 | N3: 1 | O3: 1 | P3: 1 | Q3: 1 | R3: 1 | S3: 1 | T3: 1 | U3: 1 | V3: 2 | W3: 2 | X3: 2 | Y3: 2 | Z3: 2 | AA3: 2 | AB3: 2 | AC3: 2 | AD3: 2 | AE3: 2 | AF3: 2 | AG3: 2 | AH3: 2 | AI3: 2 | AJ3: 2 | AK3: 2 | AL3: 2 | AM3: 2 | AN3: 3 | AO3: 3 | AP3: 3 | AQ3: 3 | AR3: 3 | AS3: 3 | AT3: 3 | AU3: 3 | AV3: 3 | AW3: 3 | AX3: 3 | AY3: 3 | AZ3: 3 | BA3: 3 | BB3: 3 | BC3: 3 | BD3: 3 | BE3: 3 | BF3: 4 | BG3: 4 | BH3: 4 | BI3: 4 | BJ3: 4
A4: HCP 3 | B4: 3 | E4: 1 | F4: 1 | G4: 1 | H4: 1 | I4: 1 | J4: 1 | K4: 1 | L4: 1 | M4: 1 | N4: 1 | O4: 1 | P4: 1 | Q4: 1 | R4: 1 | S4: 1 | T4: 1 | U4: 1 | V4: 1 | W4: 2 | X4: 2 | Y4: 2 | Z4: 2 | AA4: 2 | AB4: 2 | AC4: 2 | AD4: 2 | AE4: 2 | AF4: 2 | AG4: 2 | AH4: 2 | AI4: 2 | AJ4: 2 | AK4: 2 | AL4: 2 | AM4: 2 | AN4: 2 | AO4: 3 | AP4: 3 | AQ4: 3 | AR4: 3 | AS4: 3 | AT4: 3 | AU4: 3 | AV4: 3 | AW4: 3 | AX4: 3 | AY4: 3 | AZ4: 3 | BA4: 3 | BB4: 3 | BC4: 3 | BD4: 3 | BE4: 3 | BF4: 3 | BG4: 4 | BH4: 4 | BI4: 4 | BJ4: 4
A5: HCP 4 | B5: 4 | F5: 1 | G5: 1 | H5: 1 | I5: 1 | J5: 1 | K5: 1 | L5: 1 | M5: 1 | N5: 1 | O5: 1 | P5: 1 | Q5: 1 | R5: 1 | S5: 1 | T5: 1 | U5: 1 | V5: 1 | W5: 1 | X5: 2 | Y5: 2 | Z5: 2 | AA5: 2 | AB5: 2 | AC5: 2 | AD5: 2 | AE5: 2 | AF5: 2 | AG5: 2 | AH5: 2 | AI5: 2 | AJ5: 2 | AK5: 2 | AL5: 2 | AM5: 2 | AN5: 2 | AO5: 2 | AP5: 3 | AQ5: 3 | AR5: 3 | AS5: 3 | AT5: 3 | AU5: 3 | AV5: 3 | AW5: 3 | AX5: 3 | AY5: 3 | AZ5: 3 | BA5: 3 | BB5: 3 | BC5: 3 | BD5: 3 | BE5: 3 | BF5: 3 | BG5: 3 | BH5: 4 | BI5: 4 | BJ5: 4
A6: HCP 5 | B6: 5 | G6: 1 | H6: 1 | I6: 1 | J6: 1 | K6: 1 | L6: 1 | M6: 1 | N6: 1 | O6: 1 | P6: 1 | Q6: 1 | R6: 1 | S6: 1 | T6: 1 | U6: 1 | V6: 1 | W6: 1 | X6: 1 | Y6: 2 | Z6: 2 | AA6: 2 | AB6: 2 | AC6: 2 | AD6: 2 | AE6: 2 | AF6: 2 | AG6: 2 | AH6: 2 | AI6: 2 | AJ6: 2 | AK6: 2 | AL6: 2 | AM6: 2 | AN6: 2 | AO6: 2 | AP6: 2 | AQ6: 3 | AR6: 3 | AS6: 3 | AT6: 3 | AU6: 3 | AV6: 3 | AW6: 3 | AX6: 3 | AY6: 3 | AZ6: 3 | BA6: 3 | BB6: 3 | BC6: 3 | BD6: 3 | BE6: 3 | BF6: 3 | BG6: 3 | BH6: 3 | BI6: 4 | BJ6: 4
A7: HCP 6 | B7: 6 | H7: 1 | I7: 1 | J7: 1 | K7: 1 | L7: 1 | M7: 1 | N7: 1 | O7: 1 | P7: 1 | Q7: 1 | R7: 1 | S7: 1 | T7: 1 | U7: 1 | V7: 1 | W7: 1 | X7: 1 | Y7: 1 | Z7: 2 | AA7: 2 | AB7: 2 | AC7: 2 | AD7: 2 | AE7: 2 | AF7: 2 | AG7: 2 | AH7: 2 | AI7: 2 | AJ7: 2 | AK7: 2 | AL7: 2 | AM7: 2 | AN7: 2 | AO7: 2 | AP7: 2 | AQ7: 2 | AR7: 3 | AS7: 3 | AT7: 3 | AU7: 3 | AV7: 3 | AW7: 3 | AX7: 3 | AY7: 3 | AZ7: 3 | BA7: 3 | BB7: 3 | BC7: 3 | BD7: 3 | BE7: 3 | BF7: 3 | BG7: 3 | BH7: 3 | BI7: 3 | BJ7: 4
A8: HCP 7 | B8: 7 | I8: 1 | J8: 1 | K8: 1 | L8: 1 | M8: 1 | N8: 1 | O8: 1 | P8: 1 | Q8: 1 | R8: 1 | S8: 1 | T8: 1 | U8: 1 | V8: 1 | W8: 1 | X8: 1 | Y8: 1 | Z8: 1 | AA8: 2 | AB8: 2 | AC8: 2 | AD8: 2 | AE8: 2 | AF8: 2 | AG8: 2 | AH8: 2 | AI8: 2 | AJ8: 2 | AK8: 2 | AL8: 2 | AM8: 2 | AN8: 2 | AO8: 2 | AP8: 2 | AQ8: 2 | AR8: 2 | AS8: 3 | AT8: 3 | AU8: 3 | AV8: 3 | AW8: 3 | AX8: 3 | AY8: 3 | AZ8: 3 | BA8: 3 | BB8: 3 | BC8: 3 | BD8: 3 | BE8: 3 | BF8: 3 | BG8: 3 | BH8: 3 | BI8: 3 | BJ8: 3
A9: HCP 8 | B9: 8 | J9: 1 | K9: 1 | L9: 1 | M9: 1 | N9: 1 | O9: 1 | P9: 1 | Q9: 1 | R9: 1 | S9: 1 | T9: 1 | U9: 1 | V9: 1 | W9: 1 | X9: 1 | Y9: 1 | Z9: 1 | AA9: 1 | AB9: 2 | AC9: 2 | AD9: 2 | AE9: 2 | AF9: 2 | AG9: 2 | AH9: 2 | AI9: 2 | AJ9: 2 | AK9: 2 | AL9: 2 | AM9: 2 | AN9: 2 | AO9: 2 | AP9: 2 | AQ9: 2 | AR9: 2 | AS9: 2 | AT9: 3 | AU9: 3 | AV9: 3 | AW9: 3 | AX9: 3 | AY9: 3 | AZ9: 3 | BA9: 3 | BB9: 3 | BC9: 3 | BD9: 3 | BE9: 3 | BF9: 3 | BG9: 3 | BH9: 3 | BI9: 3 | BJ9: 3
A10: HCP 9 | B10: 9 | K10: 1 | L10: 1 | M10: 1 | N10: 1 | O10: 1 | P10: 1 | Q10: 1 | R10: 1 | S10: 1 | T10: 1 | U10: 1 | V10: 1 | W10: 1 | X10: 1 | Y10: 1 | Z10: 1 | AA10: 1 | AB10: 1 | AC10: 2 | AD10: 2 | AE10: 2 | AF10: 2 | AG10: 2 | AH10: 2 | AI10: 2 | AJ10: 2 | AK10: 2 | AL10: 2 | AM10: 2 | AN10: 2 | AO10: 2 | AP10: 2 | AQ10: 2 | AR10: 2 | AS10: 2 | AT10: 2 | AU10: 3 | AV10: 3 | AW10: 3 | AX10: 3 | AY10: 3 | AZ10: 3 | BA10: 3 | BB10: 3 | BC10: 3 | BD10: 3 | BE10: 3 | BF10: 3 | BG10: 3 | BH10: 3 | BI10: 3 | BJ10: 3
A11: HCP 10 | B11: 10 | L11: 1 | M11: 1 | N11: 1 | O11: 1 | P11: 1 | Q11: 1 | R11: 1 | S11: 1 | T11: 1 | U11: 1 | V11: 1 | W11: 1 | X11: 1 | Y11: 1 | Z11: 1 | AA11: 1 | AB11: 1 | AC11: 1 | AD11: 2 | AE11: 2 | AF11: 2 | AG11: 2 | AH11: 2 | AI11: 2 | AJ11: 2 | AK11: 2 | AL11: 2 | AM11: 2 | AN11: 2 | AO11: 2 | AP11: 2 | AQ11: 2 | AR11: 2 | AS11: 2 | AT11: 2 | AU11: 2 | AV11: 3 | AW11: 3 | AX11: 3 | AY11: 3 | AZ11: 3 | BA11: 3 | BB11: 3 | BC11: 3 | BD11: 3 | BE11: 3 | BF11: 3 | BG11: 3 | BH11: 3 | BI11: 3 | BJ11: 3
A12: HCP 11 | B12: 11 | M12: 1 | N12: 1 | O12: 1 | P12: 1 | Q12: 1 | R12: 1 | S12: 1 | T12: 1 | U12: 1 | V12: 1 | W12: 1 | X12: 1 | Y12: 1 | Z12: 1 | AA12: 1 | AB12: 1 | AC12: 1 | AD12: 1 | AE12: 2 | AF12: 2 | AG12: 2 | AH12: 2 | AI12: 2 | AJ12: 2 | AK12: 2 | AL12: 2 | AM12: 2 | AN12: 2 | AO12: 2 | AP12: 2 | AQ12: 2 | AR12: 2 | AS12: 2 | AT12: 2 | AU12: 2 | AV12: 2 | AW12: 3 | AX12: 3 | AY12: 3 | AZ12: 3 | BA12: 3 | BB12: 3 | BC12: 3 | BD12: 3 | BE12: 3 | BF12: 3 | BG12: 3 | BH12: 3 | BI12: 3 | BJ12: 3
A13: HCP 12 | B13: 12 | N13: 1 | O13: 1 | P13: 1 | Q13: 1 | R13: 1 | S13: 1 | T13: 1 | U13: 1 | V13: 1 | W13: 1 | X13: 1 | Y13: 1 | Z13: 1 | AA13: 1 | AB13: 1 | AC13: 1 | AD13: 1 | AE13: 1 | AF13: 2 | AG13: 2 | AH13: 2 | AI13: 2 | AJ13: 2 | AK13: 2 | AL13: 2 | AM13: 2 | AN13: 2 | AO13: 2 | AP13: 2 | AQ13: 2 | AR13: 2 | AS13: 2 | AT13: 2 | AU13: 2 | AV13: 2 | AW13: 2 | AX13: 3 | AY13: 3 | AZ13: 3 | BA13: 3 | BB13: 3 | BC13: 3 | BD13: 3 | BE13: 3 | BF13: 3 | BG13: 3 | BH13: 3 | BI13: 3 | BJ13: 3
A14: HCP 13 | B14: 13 | O14: 1 | P14: 1 | Q14: 1 | R14: 1 | S14: 1 | T14: 1 | U14: 1 | V14: 1 | W14: 1 | X14: 1 | Y14: 1 | Z14: 1 | AA14: 1 | AB14: 1 | AC14: 1 | AD14: 1 | AE14: 1 | AF14: 1 | AG14: 2 | AH14: 2 | AI14: 2 | AJ14: 2 | AK14: 2 | AL14: 2 | AM14: 2 | AN14: 2 | AO14: 2 | AP14: 2 | AQ14: 2 | AR14: 2 | AS14: 2 | AT14: 2 | AU14: 2 | AV14: 2 | AW14: 2 | AX14: 2 | AY14: 3 | AZ14: 3 | BA14: 3 | BB14: 3 | BC14: 3 | BD14: 3 | BE14: 3 | BF14: 3 | BG14: 3 | BH14: 3 | BI14: 3 | BJ14: 3
A15: HCP 14 | B15: 14 | P15: 1 | Q15: 1 | R15: 1 | S15: 1 | T15: 1 | U15: 1 | V15: 1 | W15: 1 | X15: 1 | Y15: 1 | Z15: 1 | AA15: 1 | AB15: 1 | AC15: 1 | AD15: 1 | AE15: 1 | AF15: 1 | AG15: 1 | AH15: 2 | AI15: 2 | AJ15: 2 | AK15: 2 | AL15: 2 | AM15: 2 | AN15: 2 | AO15: 2 | AP15: 2 | AQ15: 2 | AR15: 2 | AS15: 2 | AT15: 2 | AU15: 2 | AV15: 2 | AW15: 2 | AX15: 2 | AY15: 2 | AZ15: 3 | BA15: 3 | BB15: 3 | BC15: 3 | BD15: 3 | BE15: 3 | BF15: 3 | BG15: 3 | BH15: 3 | BI15: 3 | BJ15: 3
A16: HCP 15 | B16: 15 | Q16: 1 | R16: 1 | S16: 1 | T16: 1 | U16: 1 | V16: 1 | W16: 1 | X16: 1 | Y16: 1 | Z16: 1 | AA16: 1 | AB16: 1 | AC16: 1 | AD16: 1 | AE16: 1 | AF16: 1 | AG16: 1 | AH16: 1 | AI16: 2 | AJ16: 2 | AK16: 2 | AL16: 2 | AM16: 2 | AN16: 2 | AO16: 2 | AP16: 2 | AQ16: 2 | AR16: 2 | AS16: 2 | AT16: 2 | AU16: 2 | AV16: 2 | AW16: 2 | AX16: 2 | AY16: 2 | AZ16: 2 | BA16: 3 | BB16: 3 | BC16: 3 | BD16: 3 | BE16: 3 | BF16: 3 | BG16: 3 | BH16: 3 | BI16: 3 | BJ16: 3
A17: HCP 16 | B17: 16 | R17: 1 | S17: 1 | T17: 1 | U17: 1 | V17: 1 | W17: 1 | X17: 1 | Y17: 1 | Z17: 1 | AA17: 1 | AB17: 1 | AC17: 1 | AD17: 1 | AE17: 1 | AF17: 1 | AG17: 1 | AH17: 1 | AI17: 1 | AJ17: 2 | AK17: 2 | AL17: 2 | AM17: 2 | AN17: 2 | AO17: 2 | AP17: 2 | AQ17: 2 | AR17: 2 | AS17: 2 | AT17: 2 | AU17: 2 | AV17: 2 | AW17: 2 | AX17: 2 | AY17: 2 | AZ17: 2 | BA17: 2 | BB17: 3 | BC17: 3 | BD17: 3 | BE17: 3 | BF17: 3 | BG17: 3 | BH17: 3 | BI17: 3 | BJ17: 3
A18: HCP 17 | B18: 17 | S18: 1 | T18: 1 | U18: 1 | V18: 1 | W18: 1 | X18: 1 | Y18: 1 | Z18: 1 | AA18: 1 | AB18: 1 | AC18: 1 | AD18: 1 | AE18: 1 | AF18: 1 | AG18: 1 | AH18: 1 | AI18: 1 | AJ18: 1 | AK18: 2 | AL18: 2 | AM18: 2 | AN18: 2 | AO18: 2 | AP18: 2 | AQ18: 2 | AR18: 2 | AS18: 2 | AT18: 2 | AU18: 2 | AV18: 2 | AW18: 2 | AX18: 2 | AY18: 2 | AZ18: 2 | BA18: 2 | BB18: 2 | BC18: 3 | BD18: 3 | BE18: 3 | BF18: 3 | BG18: 3 | BH18: 3 | BI18: 3 | BJ18: 3 | BR18: 3
A19: HCP 18 | B19: 18 | T19: 1 | U19: 1 | V19: 1 | W19: 1 | X19: 1 | Y19: 1 | Z19: 1 | AA19: 1 | AB19: 1 | AC19: 1 | AD19: 1 | AE19: 1 | AF19: 1 | AG19: 1 | AH19: 1 | AI19: 1 | AJ19: 1 | AK19: 1 | AL19: 2 | AM19: 2 | AN19: 2 | AO19: 2 | AP19: 2 | AQ19: 2 | AR19: 2 | AS19: 2 | AT19: 2 | AU19: 2 | AV19: 2 | AW19: 2 | AX19: 2 | AY19: 2 | AZ19: 2 | BA19: 2 | BB19: 2 | BC19: 2 | BD19: 3 | BE19: 3 | BF19: 3 | BG19: 3 | BH19: 3 | BI19: 3 | BJ19: 3

Sheet HCP
A1: DGV-Vorgabenklasse | B1: DGV-Stammvorgaben | C1: Pufferzone | D1: Heraufsetzungswert | E1: Herabsetzungsmultiplikand für jeden Punkt oberhalb der Pufferzone
C2: gewertete Stableford-Nettopunkte
A6: 1 | B6: bis 4,4 | C6: 35 | D6: 0.1 | E6: 0.1
A7: 2 | B7: 4,5 bis 11,4 | C7: 34 | D7: 0.1 | E7: 0.2
A8: 3 | B8: 11,5 bis 18,4 | C8: 33 | D8: 0.1 | E8: 0.3
A9: 4 | B9: 18,5 bis 26,4 | C9: 32 | D9: 0.1 | E9: 0.4
A10: 5 | B10: 26,5 bis 36,0 | C10: 31 | D10: 0.2 | E10: 0.5
A11: 6 | B11: 37 bis 54 | C11: 0 | D11: 0 | E11: 1
A13: HCP | C13: 25.1
A14: Stammv. | C14: 22
A15: Netto | C15: 37
A17: Vorgabeklasse | C17: =IF(C14<4.4,1,IF(AND(C14>=4.5,C14<=11.4),2,IF(AND(C14>=11.5,C14<=18.4),3,IF(AND(C14>=18.5,C14<=26.4),4,IF(AND(C14>=26.5,C14<=36),5,IF(C14>=36,6)))))) -> 4
A18: Pufferzone | C18: =VLOOKUP(C17,$A$6:$C$11,3,FALSE) -> 32
C20: =IF(C15>36,"Herabsetzung",IF(AND(C15<=36,C15>=C18),"Puffer","Heraufsetzung")) -> Herabsetzung
A22: Neues HCP | C22: =IF($C$20="Heraufsetzung",INDEX($C$395:$D$755,MATCH($C$13,$C$394:$C$755,0),MATCH($A$22,$D$394,0)),IF($C$20="Puffer",$C$13,IF($C$20="Herabsetzung",INDEX($C$29:$AK$389,MATCH($C$13,$C$29:$C$389,0),MATCH($C$15,$C$28:$AK$28,0))))) -> 24.7
D26: Herabsetzung
D27: Netto-Punkte gem. Stableford bei Herabsetzung
C28: HCP | D28: 37 | E28: 38 | F28: 39 | G28: 40 | H28: 41 | I28: 42 | J28: 43 | K28: 44 | L28: 45 | M28: 46 | N28: 47 | O28: 48 | P28: 49 | Q28: 50 | R28: 51 | S28: 52 | T28: 53 | U28: 54 | V28: 55 | W28: 56 | X28: 57 | Y28: 58 | Z28: 59 | AA28: 60 | AB28: 61 | AC28: 62 | AD28: 63 | AE28: 64 | AF28: 65 | AG28: 66 | AH28: 67 | AI28: 68 | AJ28: 69 | AK28: 70
C29: 0 | D29: =(IF(C29<=4.4,C29-$E$6,IF(AND(C29>=4.5,C29<=11.4),C29-$E$7,IF(AND(C29>=11.5,C29<=18.4),C29-$E$8,IF(AND(C29>=18.5,C29<=26.4),C29-$E$9,IF(AND(C29>=26.4,C29<=36),C29-$E$10,IF(C29>=37,C29-$E$11))))))) -> -0.1 | E29: =(IF(D29<=4.4,D29-$E$6,IF(AND(D29>=4.5,D29<=11.4),D29-$E$7,IF(AND(D29>=11.5,D29<=18.4),D29-$E$8,IF(AND(D29>=18.5,D29<=26.4),D29-$E$9,IF(AND(D29>=26.4,D29<=36),D29-$E$10,IF(D29>=37,D29-$E$11))))))) -> -0.2 | F29: =(IF(E29<=4.4,E29-$E$6,IF(AND(E29>=4.5,E29<=11.4),E29-$E$7,IF(AND(E29>=11.5,E29<=18.4),E29-$E$8,IF(AND(E29>=18.5,E29<=26.4),E29-$E$9,IF(AND(E29>=26.4,E29<=36),E29-$E$10,IF(E29>=37,E29-$E$11))))))) -> -0.3 | G29: =(IF(F29<=4.4,F29-$E$6,IF(AND(F29>=4.5,F29<=11.4),F29-$E$7,IF(AND(F29>=11.5,F29<=18.4),F29-$E$8,IF(AND(F29>=18.5,F29<=26.4),F29-$E$9,IF(AND(F29>=26.4,F29<=36),F29-$E$10,IF(F29>=37,F29-$E$11))))))) -> -0.4 | H29: =(IF(G29<=4.4,G29-$E$6,IF(AND(G29>=4.5,G29<=11.4),G29-$E$7,IF(AND(G29>=11.5,G29<=18.4),G29-$E$8,IF(AND(G29>=18.5,G29<=26.4),G29-$E$9,IF(AND(G29>=26.4,G29<=36),G29-$E$10,IF(G29>=37,G29-$E$11))))))) -> -0.5 | I29: =(IF(H29<=4.4,H29-$E$6,IF(AND(H29>=4.5,H29<=11.4),H29-$E$7,IF(AND(H29>=11.5,H29<=18.4),H29-$E$8,IF(AND(H29>=18.5,H29<=26.4),H29-$E$9,IF(AND(H29>=26.4,H29<=36),H29-$E$10,IF(H29>=37,H29-$E$11))))))) -> -0.6 | J29: =(IF(I29<=4.4,I29-$E$6,IF(AND(I29>=4.5,I29<=11.4),I29-$E$7,IF(AND(I29>=11.5,I29<=18.4),I29-$E$8,IF(AND(I29>=18.5,I29<=26.4),I29-$E$9,IF(AND(I29>=26.4,I29<=36),I29-$E$10,IF(I29>=37,I29-$E$11))))))) -> -0.7 | K29: =(IF(J29<=4.4,J29-$E$6,IF(AND(J29>=4.5,J29<=11.4),J29-$E$7,IF(AND(J29>=11.5,J29<=18.4),J29-$E$8,IF(AND(J29>=18.5,J29<=26.4),J29-$E$9,IF(AND(J29>=26.4,J29<=36),J29-$E$10,IF(J29>=37,J29-$E$11))))))) -> -0.8 | ... AK29: =(IF(AJ29<=4.4,AJ29-$E$6,IF(AND(AJ29>=4.5,AJ29<=11.4),AJ29-$E$7,IF(AND(AJ29>=11.5,AJ29<=18.4),AJ29-$E$8,IF(AND(AJ29>=18.5,AJ29<=26.4),AJ29-$E$9,IF(AND(AJ29>=26.4,AJ29<=36),AJ29-$E$10,IF(AJ29>=37,AJ29-$E$11))))))) -> -3.4
C30: 0.1 | D30: =(IF(C30<=4.4,C30-$E$6,IF(AND(C30>=4.5,C30<=11.4),C30-$E$7,IF(AND(C30>=11.5,C30<=18.4),C30-$E$8,IF(AND(C30>=18.5,C30<=26.4),C30-$E$9,IF(AND(C30>=26.4,C30<=36),C30-$E$10,IF(C30>=37,C30-$E$11))))))) -> 0 | E30: =(IF(D30<=4.4,D30-$E$6,IF(AND(D30>=4.5,D30<=11.4),D30-$E$7,IF(AND(D30>=11.5,D30<=18.4),D30-$E$8,IF(AND(D30>=18.5,D30<=26.4),D30-$E$9,IF(AND(D30>=26.4,D30<=36),D30-$E$10,IF(D30>=37,D30-$E$11))))))) -> -0.1 | F30: =(IF(E30<=4.4,E30-$E$6,IF(AND(E30>=4.5,E30<=11.4),E30-$E$7,IF(AND(E30>=11.5,E30<=18.4),E30-$E$8,IF(AND(E30>=18.5,E30<=26.4),E30-$E$9,IF(AND(E30>=26.4,E30<=36),E30-$E$10,IF(E30>=37,E30-$E$11))))))) -> -0.2 | G30: =(IF(F30<=4.4,F30-$E$6,IF(AND(F30>=4.5,F30<=11.4),F30-$E$7,IF(AND(F30>=11.5,F30<=18.4),F30-$E$8,IF(AND(F30>=18.5,F30<=26.4),F30-$E$9,IF(AND(F30>=26.4,F30<=36),F30-$E$10,IF(F30>=37,F30-$E$11))))))) -> -0.3 | H30: =(IF(G30<=4.4,G30-$E$6,IF(AND(G30>=4.5,G30<=11.4),G30-$E$7,IF(AND(G30>=11.5,G30<=18.4),G30-$E$8,IF(AND(G30>=18.5,G30<=26.4),G30-$E$9,IF(AND(G30>=26.4,G30<=36),G30-$E$10,IF(G30>=37,G30-$E$11))))))) -> -0.4 | I30: =(IF(H30<=4.4,H30-$E$6,IF(AND(H30>=4.5,H30<=11.4),H30-$E$7,IF(AND(H30>=11.5,H30<=18.4),H30-$E$8,IF(AND(H30>=18.5,H30<=26.4),H30-$E$9,IF(AND(H30>=26.4,H30<=36),H30-$E$10,IF(H30>=37,H30-$E$11))))))) -> -0.5 | J30: =(IF(I30<=4.4,I30-$E$6,IF(AND(I30>=4.5,I30<=11.4),I30-$E$7,IF(AND(I30>=11.5,I30<=18.4),I30-$E$8,IF(AND(I30>=18.5,I30<=26.4),I30-$E$9,IF(AND(I30>=26.4,I30<=36),I30-$E$10,IF(I30>=37,I30-$E$11))))))) -> -0.6 | K30: =(IF(J30<=4.4,J30-$E$6,IF(AND(J30>=4.5,J30<=11.4),J30-$E$7,IF(AND(J30>=11.5,J30<=18.4),J30-$E$8,IF(AND(J30>=18.5,J30<=26.4),J30-$E$9,IF(AND(J30>=26.4,J30<=36),J30-$E$10,IF(J30>=37,J30-$E$11))))))) -> -0.7 | ... AK30: =(IF(AJ30<=4.4,AJ30-$E$6,IF(AND(AJ30>=4.5,AJ30<=11.4),AJ30-$E$7,IF(AND(AJ30>=11.5,AJ30<=18.4),AJ30-$E$8,IF(AND(AJ30>=18.5,AJ30<=26.4),AJ30-$E$9,IF(AND(AJ30>=26.4,AJ30<=36),AJ30-$E$10,IF(AJ30>=37,AJ30-$E$11))))))) -> -3.3
C31: 0.2 | D31: =(IF(C31<=4.4,C31-$E$6,IF(AND(C31>=4.5,C31<=11.4),C31-$E$7,IF(AND(C31>=11.5,C31<=18.4),C31-$E$8,IF(AND(C31>=18.5,C31<=26.4),C31-$E$9,IF(AND(C31>=26.4,C31<=36),C31-$E$10,IF(C31>=37,C31-$E$11))))))) -> 0.1 | E31: =(IF(D31<=4.4,D31-$E$6,IF(AND(D31>=4.5,D31<=11.4),D31-$E$7,IF(AND(D31>=11.5,D31<=18.4),D31-$E$8,IF(AND(D31>=18.5,D31<=26.4),D31-$E$9,IF(AND(D31>=26.4,D31<=36),D31-$E$10,IF(D31>=37,D31-$E$11))))))) -> 0 | F31: =(IF(E31<=4.4,E31-$E$6,IF(AND(E31>=4.5,E31<=11.4),E31-$E$7,IF(AND(E31>=11.5,E31<=18.4),E31-$E$8,IF(AND(E31>=18.5,E31<=26.4),E31-$E$9,IF(AND(E31>=26.4,E31<=36),E31-$E$10,IF(E31>=37,E31-$E$11))))))) -> -0.1 | G31: =(IF(F31<=4.4,F31-$E$6,IF(AND(F31>=4.5,F31<=11.4),F31-$E$7,IF(AND(F31>=11.5,F31<=18.4),F31-$E$8,IF(AND(F31>=18.5,F31<=26.4),F31-$E$9,IF(AND(F31>=26.4,F31<=36),F31-$E$10,IF(F31>=37,F31-$E$11))))))) -> -0.2 | H31: =(IF(G31<=4.4,G31-$E$6,IF(AND(G31>=4.5,G31<=11.4),G31-$E$7,IF(AND(G31>=11.5,G31<=18.4),G31-$E$8,IF(AND(G31>=18.5,G31<=26.4),G31-$E$9,IF(AND(G31>=26.4,G31<=36),G31-$E$10,IF(G31>=37,G31-$E$11))))))) -> -0.3 | I31: =(IF(H31<=4.4,H31-$E$6,IF(AND(H31>=4.5,H31<=11.4),H31-$E$7,IF(AND(H31>=11.5,H31<=18.4),H31-$E$8,IF(AND(H31>=18.5,H31<=26.4),H31-$E$9,IF(AND(H31>=26.4,H31<=36),H31-$E$10,IF(H31>=37,H31-$E$11))))))) -> -0.4 | J31: =(IF(I31<=4.4,I31-$E$6,IF(AND(I31>=4.5,I31<=11.4),I31-$E$7,IF(AND(I31>=11.5,I31<=18.4),I31-$E$8,IF(AND(I31>=18.5,I31<=26.4),I31-$E$9,IF(AND(I31>=26.4,I31<=36),I31-$E$10,IF(I31>=37,I31-$E$11))))))) -> -0.5 | K31: =(IF(J31<=4.4,J31-$E$6,IF(AND(J31>=4.5,J31<=11.4),J31-$E$7,IF(AND(J31>=11.5,J31<=18.4),J31-$E$8,IF(AND(J31>=18.5,J31<=26.4),J31-$E$9,IF(AND(J31>=26.4,J31<=36),J31-$E$10,IF(J31>=37,J31-$E$11))))))) -> -0.6 | ... AK31: =(IF(AJ31<=4.4,AJ31-$E$6,IF(AND(AJ31>=4.5,AJ31<=11.4),AJ31-$E$7,IF(AND(AJ31>=11.5,AJ31<=18.4),AJ31-$E$8,IF(AND(AJ31>=18.5,AJ31<=26.4),AJ31-$E$9,IF(AND(AJ31>=26.4,AJ31<=36),AJ31-$E$10,IF(AJ31>=37,AJ31-$E$11))))))) -> -3.2
C32: 0.3 | D32: =(IF(C32<=4.4,C32-$E$6,IF(AND(C32>=4.5,C32<=11.4),C32-$E$7,IF(AND(C32>=11.5,C32<=18.4),C32-$E$8,IF(AND(C32>=18.5,C32<=26.4),C32-$E$9,IF(AND(C32>=26.4,C32<=36),C32-$E$10,IF(C32>=37,C32-$E$11))))))) -> 0.2 | E32: =(IF(D32<=4.4,D32-$E$6,IF(AND(D32>=4.5,D32<=11.4),D32-$E$7,IF(AND(D32>=11.5,D32<=18.4),D32-$E$8,IF(AND(D32>=18.5,D32<=26.4),D32-$E$9,IF(AND(D32>=26.4,D32<=36),D32-$E$10,IF(D32>=37,D32-$E$11))))))) -> 0.1 | F32: =(IF(E32<=4.4,E32-$E$6,IF(AND(E32>=4.5,E32<=11.4),E32-$E$7,IF(AND(E32>=11.5,E32<=18.4),E32-$E$8,IF(AND(E32>=18.5,E32<=26.4),E32-$E$9,IF(AND(E32>=26.4,E32<=36),E32-$E$10,IF(E32>=37,E32-$E$11))))))) -> -2.7755576e-17 | G32: =(IF(F32<=4.4,F32-$E$6,IF(AND(F32>=4.5,F32<=11.4),F32-$E$7,IF(AND(F32>=11.5,F32<=18.4),F32-$E$8,IF(AND(F32>=18.5,F32<=26.4),F32-$E$9,IF(AND(F32>=26.4,F32<=36),F32-$E$10,IF(F32>=37,F32-$E$11))))))) -> -0.1 | H32: =(IF(G32<=4.4,G32-$E$6,IF(AND(G32>=4.5,G32<=11.4),G32-$E$7,IF(AND(G32>=11.5,G32<=18.4),G32-$E$8,IF(AND(G32>=18.5,G32<=26.4),G32-$E$9,IF(AND(G32>=26.4,G32<=36),G32-$E$10,IF(G32>=37,G32-$E$11))))))) -> -0.2 | I32: =(IF(H32<=4.4,H32-$E$6,IF(AND(H32>=4.5,H32<=11.4),H32-$E$7,IF(AND(H32>=11.5,H32<=18.4),H32-$E$8,IF(AND(H32>=18.5,H32<=26.4),H32-$E$9,IF(AND(H32>=26.4,H32<=36),H32-$E$10,IF(H32>=37,H32-$E$11))))))) -> -0.3 | J32: =(IF(I32<=4.4,I32-$E$6,IF(AND(I32>=4.5,I32<=11.4),I32-$E$7,IF(AND(I32>=11.5,I32<=18.4),I32-$E$8,IF(AND(I32>=18.5,I32<=26.4),I32-$E$9,IF(AND(I32>=26.4,I32<=36),I32-$E$10,IF(I32>=37,I32-$E$11))))))) -> -0.4 | K32: =(IF(J32<=4.4,J32-$E$6,IF(AND(J32>=4.5,J32<=11.4),J32-$E$7,IF(AND(J32>=11.5,J32<=18.4),J32-$E$8,IF(AND(J32>=18.5,J32<=26.4),J32-$E$9,IF(AND(J32>=26.4,J32<=36),J32-$E$10,IF(J32>=37,J32-$E$11))))))) -> -0.5 | ... AK32: =(IF(AJ32<=4.4,AJ32-$E$6,IF(AND(AJ32>=4.5,AJ32<=11.4),AJ32-$E$7,IF(AND(AJ32>=11.5,AJ32<=18.4),AJ32-$E$8,IF(AND(AJ32>=18.5,AJ32<=26.4),AJ32-$E$9,IF(AND(AJ32>=26.4,AJ32<=36),AJ32-$E$10,IF(AJ32>=37,AJ32-$E$11))))))) -> -3.1
